Workbook

Sheet Tibetan
A1: Category | B1: Main files | C1: Sentence- Segn E-text link | D1: Type རྒྱུ་ཆའི་རིགས། | E1: Google doc Link | F1: Metadata | G1: མཛད་པ་པོ། | H1: མཚན་བྱང་། | I1: Title | J1: Author name | K1: Website link བརྩམས་ཆོས་དྲ་ཐག
A2: སློབ་གྲྭ་ཁག་གི་སྔ་དགོང་ཞལ་འདོན། | B2: M0CD39D50 སྐྱབས་སེམས་སྦྲགས་མ། | C2: M0CD39D50 སྐྱབས་སེམས་སྦྲགས་མ། Segmentation | D2: རྩ་བ། | E2: https://docs.google.com/document/d/1bpv1eOSS8xkQa-grERLG_i_UN7TlgctAAH25_r_w5cM/edit?tab=t.0 | F2: https://docs.google.com/spreadsheets/d/1cQDmJO4GXozqMveD67NX8iMYZgKccIZSQNLtKYwq4q8/edit?gid=0#gid=0 | G2: =authors!A15 -> ཇོ་བོ་རྗེ་དཔལ་ལྡན་ཨ་ཏི་ཤ | H2: སྐྱབས་སེམས་སྦྲགས་མ། | K2: http://purl.bdrc.io/resource/WA0XL9ED6898E9FE8
A3: སློབ་གྲྭ་ཁག་གི་སྔ་དགོང་ཞལ་འདོན། | B3: R2BAAB220 ༈ སངས་རྒྱས་ཆོས་ཚོགས་མའི་འབྲུ་འགྲེལ། | C3: R2BAAB220 ༈ སངས་རྒྱས་ཆོས་ཚོགས་མའི་འབྲུ་འགྲེལ། Segmentaton - corrected | D3: འགྲེལ་བ། {ཡི་གེ} | G3: =authors!A96 -> ཧི་མ་ལ་ཡའི་འཕྲུལ་སྨྱུག | H3: ༈ སངས་རྒྱས་ཆོས་ཚོགས་མའི་འབྲུ་འགྲེལ། | K3: https://www.khabdha.org/%E0%BC%88-%E0%BD%A6%E0%BD%84%E0%BD%A6%E0%BC%8B%E0%BD%A2%E0%BE%92%E0%BE%B1%E0%BD%A6%E0%BC%8B%E0%BD%86%E0%BD%BC%E0%BD%A6%E0%BC%8B%E0%BD%9A%E0%BD%BC%E0%BD%82%E0%BD%A6%E0%BC%8B%E0%BD%98%E0%BD%A0/
A4: སློབ་གྲྭ་ཁག་གི་སྔ་དགོང་ཞལ་འདོན། | B4: RB488199D སྐྱབས་སེམས་སངས་རྒྱས་ཆོས་ཚོགས་མའི་འགྲེལ་པ་མདོར་བསྡུས ༼སྐྱབས་སེམས་འགྲེལ་པ༽ | C4: RB488199D སྐྱབས་སེམས་སངས་རྒྱས་ཆོས་ཚོགས་མའི་འགྲེལ་པ་མདོར་བསྡུས ༼སྐྱབས་སེམས་འགྲེལ་པ༽Segmentation - corrected | D4: འགྲེལ་བ། {ཡི་གེ} | G4: =authors!A67 -> རྫ་རོང་ཕུ་སྤྲུལ་སྐུ་ངག་དབང་བསྟན་འཛིན་ནོར་བུ། | H4: སྐྱབས་སེམས་སངས་རྒྱས་ཆོས་ཚོགས་མའི་འགྲེལ་པ་མདོར་བསྡུས ༼སྐྱབས་སེམས་འགྲེལ་པ༽ | K4: http://purl.bdrc.io/resource/WA0XL1A38B0903465
A5: སློབ་གྲྭ་ཁག་གི་སྔ་དགོང་ཞལ་འདོན། | B5: R5ED0E774 སྐྱབས་སེམས་ཀྱི་ཁྲིད་བསྡུས་སངས་རྒྱས་ཆོས་ཚོགས་མའི་འགྲེལ་པ། | C5: R5ED0E774 སྐྱབས་སེམས་ཀྱི་ཁྲིད་བསྡུས་སངས་རྒྱས་ཆོས་ཚོགས་མའི་འགྲེལ་པ། Sementation - corrected | D5: འགྲེལ་བ། {ཡི་གེ} | G5: རྫ་དཔལ་སྤྲུལ་ཨོ་རྒྱན་འཇིགས་མེད་ཆོས་ཀྱི་དབང་པོ། | H5: སྐྱབས་སེམས་ཀྱི་ཁྲིད་བསྡུས་སངས་རྒྱས་ཆོས་ཚོགས་མའི་འགྲེལ་པ། | K5: http://purl.bdrc.io/resource/WA0XLE93FBDBA4082
A6: སློབ་གྲྭ་ཁག་གི་སྔ་དགོང་ཞལ་འདོན། | B6: R3DD5DE8D སངས་རྒྱས་ཆོས་ཚོགས་མའི་ཚིག་དོན། | C6: R3DD5DE8D སངས་རྒྱས་ཆོས་ཚོགས་མའི་ཚིག་དོན། Sementation - corrected | D6: འགྲེལ་བ། {ཡི་གེ} | G6: =authors!A23 -> དགེ་བཤེས་བློ་བཟང་ཟླ་བ། | H6: སངས་རྒྱས་ཆོས་ཚོགས་མའི་ཚིག་དོན། | K6: དེབ་གཟུགས་ནས་འཕྲུལ་དེབ་བཟོས་ཡོད་པས་དྲྭ་ཐག་མེད།
A7: སློབ་གྲྭ་ཁག་གི་སྔ་དགོང་ཞལ་འདོན། | B7: R54F2B5E5 སྐྱབས་སེམས་བསྡུས་འགྲེལ་དོན་གསལ་མེ་ལོང་། | C7: R45CAD476 སྐྱབས་འགྲོ་སེམས་བསྐྱེད་ཤིན་ཏུ་བསྡུས་པ། Segmentation - corrected | D7: འགྲེལ་བ། {ཡི་གེ} | G7: =authors!A43 -> བླ་མ་ཞང་བརྩོན་འགྲུས་གྲགས་པ། | H7: སྐྱབས་འགྲོ་སེམས་བསྐྱེད་ཤིན་དུ་བསྡུས་པ། | K7: http://purl.bdrc.io/resource/WA0XL73F02E99B2E2
A8: སློབ་གྲྭ་ཁག་གི་སྔ་དགོང་ཞལ་འདོན། | B8: R45CAD476 སྐྱབས་འགྲོ་སེམས་བསྐྱེད་ཤིན་དུ་བསྡུས་པ། | C8: R54F2B5E5 སྐྱབས་སེམས་བསྡུས་འགྲེལ་དོན་གསལ་མེ་ལོང་། Segmentation - corrected | D8: འགྲེལ་བ། {ཡི་གེ} | G8: =authors!A58 -> འབྲི་གུང་ངེས་དོན་རིན་པོ་ཆེ་ངེས་དོན་འཛམ་གླིང་ཆོས་བསྒྲགས་རྒྱ་མཚོ། | H8: སྐྱབས་སེམས་བསྡུས་འགྲེལ་དོན་གསལ་མེ་ལོང་། | K8: http://purl.bdrc.io/resource/WA0XLB31A436D79CC
A9: སློབ་གྲྭ་ཁག་གི་སྔ་དགོང་ཞལ་འདོན། | B9: R9993DB53 སངས་རྒྱས་ཆོས་ཚོགས་མའི་དམིགས་རིམ། | C9: R9993DB53 སངས་རྒྱས་ཆོས་ཚོགས་མའི་དམིགས་རིམ། Segmentation | D9: འགྲེལ་བ། {ཡི་གེ} | G9: =authors!A20 -> ཐུའུ་བཀྭན ༠༣་བློ་བཟང་ཆོས་ཀྱི་ཉི་མ། | H9: སངས་རྒྱས་ཆོས་ཚོགས་མའི་དམིགས་རིམ། | K9: http://purl.bdrc.io/resource/WA0XL7226776A4368
A10: སློབ་གྲྭ་ཁག་གི་སྔ་དགོང་ཞལ་འདོན། | B10: R640CF66F སངས་རྒྱས་ཆོས་ཚོགས་མའི་བཀའ་ཁྲིད། | C10: R466EF11C སངས་རྒྱས་ཆོས་ཚོགས་མའི་འགྲེལ་པ་བཞུགས་སོ། ། Segmentation | D10: འགྲེལ་བ། {ཡི་གེ} | G10: =authors!A19 -> ཏཱ་ལའི་བླ་མ ༡༤་བསྟན་འཛིན་རྒྱ་མཚོ། | H10: སངས་རྒྱས་ཆོས་ཚོགས་མའི་འགྲེལ་པ་བཞུགས་སོ།། | K10: http://purl.bdrc.io/resource/WA4CZ294733
A11: སློབ་གྲྭ་ཁག་གི་སྔ་དགོང་ཞལ་འདོན། | B11: སྒྲོལ་མ་ཉེར་གཅིག་གི་བསྟོད་པ། | C11: MDAFBF633 སྒྲོལ་མ་ཉེར་གཅིག་གི་བསྟོད་པ། Segmentation | D11: རྩ་བ། | G11: =authors!A82 -> སངས་རྒྱས་རྣམ་པར་སྣང་མཛད། | H11: སྒྲོལ་མ་ཉེར་གཅིག་ལ་བསྟོད་པ། | K11: https://library.bdrc.io/show/bdr:MW00EGS1016759_F0FAD3?s=%2Fshow%2Fbdr%3AMW00EGS1016759%3Fpart%3Dbdr%3AMW00EGS1016759_F0FAD3#open-viewer
A12: སློབ་གྲྭ་ཁག་གི་སྔ་དགོང་ཞལ་འདོན། | B12: RAF75A533 སྒྲོལ་མའི་འགྲེལ་བ་འཕྲིན་ལས་ཆར་དུ་སྙིལ་བའི་སྤྲིན་ཕུང་། | C12: RAF75A533 སྒྲོལ་མའི་འགྲེལ་བ་འཕྲིན་ལས་ཆར་དུ་སྙིལ་བའི་སྤྲིན་ཕུང་། Segmentation | D12: འགྲེལ་བ། {ཡི་གེ} | G12: =authors!A62 -> རྗེ་བཙུན་ཡ་མ་བསོད་ནམས། | H12: སྒྲོལ་མའི་འགྲེལ་པ་འཕྲིན་ལས་ཆར་དུ་སྙིལ་པའི་སྤྲིན་ཕུང་།
A13: སློབ་གྲྭ་ཁག་གི་སྔ་དགོང་ཞལ་འདོན། | B13: R5040C72C སྒྲོལ་མ་ཕྱག་འཚལ་ཉེར་གཅིག་གི་མཆན་འགྲེལ་བཞུགས་སོ། | C13: R5040C72C སྒྲོལ་མ་ཕྱག་འཚལ་ཉེར་གཅིག་གི་མཆན་འགྲེལ་བཞུགས་སོ།11-sengmentation | D13: འགྲེལ་བ། {ཡི་གེ} | G13: =authors!A45 -> བློ་བཟང་ཟླ་བ། | H13: སྒྲོལ་མ་ཕྱག་འཚལ་ཉེར་གཅིག་གི་མཆན་འགྲེལ་བཞུགས་སོ། | K13: https://library.bdrc.io/show/bdr:MW8LS77083
A14: སློབ་གྲྭ་ཁག་གི་སྔ་དགོང་ཞལ་འདོན། | B14: R46BA3ACB སྒྲོལ་མའི་ཆོས་སྐོར།_བློ་བཟང་དགོངས་རྒྱན་དེབ།༤༢_ཤྲཱི་བོད་ཀྱི་གཙུག་ལག | C14: R46BA3ACB ༄༅། །སྒྲོལ་མར་ཕྱག་འཚལ་ཉེར་གཅིག་གིས་བསྟོད་པའི་རྣམ་བཤད་ཡིད་འཕྲོག་ཨུཏྤལའི་ཆུན་པོ་ཞེས་བྱ་བ་བཞུགས་སོ། །-segmentation | D14: འགྲེལ་བ། {ཡི་གེ} | G14: =authors!A25 -> དངུལ་ཆུ་དྷརྨ་བྷ་དྲ། | H14: སྒྲོལ་མར་ཕྱག་འཚལ་ཉེར་གཅིག་གིས་བསྟོད་པའི་རྣམ་བཤད་ཡིད་འཕྲོག་ཨུཏྤལའི་ཆུན་པོ་ཞེས་བྱ་བ་བཞུགས་སོ། ། | K14: https://www.tb1025.cn/nacuo/yande3/2019-12-01/3354.html
A15: སློབ་གྲྭ་ཁག་གི་སྔ་དགོང་ཞལ་འདོན། | B15: R4C616099 ཕྱག་འཚལ་ཉེར་གཅིག་གི་ཕན་ཡོན་དང་བཅས་པ་གསལ་བའི་མེ་ལོང་ཞེས་བྱ་བ་བཞུགས་སོ།། །། | C15: R4C616099 ཕྱག་འཚལ་ཉེར་གཅིག་གི་ཕན་ཡོན་དང་བཅས་པ་གསལ་བའི་མེ་ལོང་ཞེས་བྱ་བ་བཞུགས་སོ།། །། B-2-Segnementation | D15: འགྲེལ་བ། {ཡི་གེ} | G15: རྡོར་སློབ་བསྟན་དགའ་སྤྲུལ། | H15: ཕྱག་འཚལ་ཉེར་གཅིག་གི་ཕན་ཡོན་དང་བཅས་པ་གསལ་བའི་མེ་ལོང་ཞེས་བྱ་བ་བཞུགས་སོ།། །། | K15: https://dharmacloud.tsadra.org/pdf-reader/?pdf_url=/wp-content/uploads/PDFs_2021/BEN-LB-007.pdf
A16: སློབ་གྲྭ་ཁག་གི་སྔ་དགོང་ཞལ་འདོན། | B16: R3C5D7E26 སྒྲོལ་མ་ཉེར་གཅིག་གི་བསྟོད་འགྲེལ་སྙིང་གི་ནོར་བུ | C16: R3C5D7E26 སྒྲོལ་མ་ཉེར་གཅིག་གི་བསྟོད་འགྲེལ་སྙིང་གི་ནོར་བུ 10-Segnmentation | D16: འགྲེལ་བ། {ཡི་གེ} | G16: =authors!A94 -> སེར་སྨད་གཙང་དགེ་བཤེས་བསྟན་འཛིན་དོན་བཟང་། | H16: སྒྲོལ་མ་ཉེར་གཅིག་གི་བསྟོད་འགྲེལ་སྙིང་གི་ནོར་བུ།
A17: སློབ་གྲྭ་ཁག་གི་སྔ་དགོང་ཞལ་འདོན། | B17: RCFC0F990 ཕྱག་འཚལ་ཉེར་གཅིག་གི་བསྟོད་འགྲེལ་བདུད་རྩིའི་དགའ་ཚལ་བཞུགས་སོ།། | C17: RCFC0F990 ཕྱག་འཚལ་ཉེར་གཅིག་གི་བསྟོད་འགྲེལ་བདུད་རྩིའི་དགའ་ཚལ་བཞུགས་སོ།།- Segmentation | D17: འགྲེལ་བ། {ཡི་གེ} | G17: =authors!A55 -> ཟུར་མང་མཁན་པོ་པདྨ་རྣམ་རྒྱལ། | H17: ཕྱག་འཚལ་ཉེར་གཅིག་གི་བསྟོད་འགྲེལ་བདུད་རྩིའི་དགའ་ཚལ་བཞུགས་སོ། | K17: https://dharmacloud.tsadra.org/pdf-reader/?pdf_url=/wp-content/uploads/PDFs_2021/BEN-LB-007.pdf
A18: སློབ་གྲྭ་ཁག་གི་སྔ་དགོང་ཞལ་འདོན། | B18: R1FAE45EC སྒྲོལ་མ་ཕྱག་འཚལ་ཉི་ཤུ་རྩ་གཅིག་གི་བསྟོད་པའི་རྣམ་བཤད་གསལ་བའི་འོད་ཟེར་ཞེས་བྱ་བ་བཞུགས་སོ། | C18: R1FAE45EC སྒྲོལ་མ་ཕྱག་འཚལ་ཉི་ཤུ་རྩ་གཅིག་གི་བསྟོད་པའི་རྣམ་བཤད་གསལ་བའི་འོད་ཟེར་ཞེས་བྱ་བ་བཞུགས་སོ།-segmentation | D18: འགྲེལ་བ། {ཡི་གེ} | G18: =authors!A61 -> རྗེ་བཙུན་ཏཱ་ར་ནཱ་ཐ། | H18: སྒྲོལ་མ་ཕྱག་འཚལ་ཉི་ཤུ་རྩ་གཅིག་གི་བསྟོད་པའི་རྣམ་བཤད་གསལ་བའི་འོད་ཟེར་ཞེས་བྱ་བ་བཞུགས་སོ། | K18: https://drive.google.com/file/d/1FgH7-ShmMKQUqJZPEx1oRL5Ks5u9xbmm/view
A19: སློབ་གྲྭ་ཁག་གི་སྔ་དགོང་ཞལ་འདོན། | B19: R1F6AA6C0 སྒྲོལ་མཉེར་གཅིག་གི་རྣམ་བཤད། | C19: R1F6AA6C0 སྒྲོལ་མཉེར་གཅིག་གི་རྣམ་བཤད། -Segmentation | D19: འགྲེལ་བ། {ཡི་གེ} | G19: =authors!A27 -> དཔལ་ལྡན་ཕ་ར་རིན་ཆེན་གླིང་། | H19: སྒྲོལ་མཉེར་གཅིག་གི་རྣམ་བཤད།
A20: སློབ་གྲྭ་ཁག་གི་སྔ་དགོང་ཞལ་འདོན། | B20: R1B1817B6 སངས་རྒྱས་རྣམ་པར་སྣང་མཛད་ཀྱིས་གསུངས་པ་འཕགས་མ་སྒྲོལ་མ་ལ་བསྟོད་པ་ཕྱག་འཚལ་བ་ཉི་ཤུ་རྩ་གཅིག | C20: R1B1817B6 སངས་རྒྱས་རྣམ་པར་སྣང་མཛད་ཀྱིས་གསུངས་པ་འཕགས་མ་སྒྲོལ་མ་ལ་བསྟོད་པ་ཕྱག་འཚལ་བ་ཉི་ཤུ་རྩ་གཅིག།-Segmentation | D20: འགྲེལ་བ། {ཡི་གེ} | G20: =authors!A25 -> དངུལ་ཆུ་དྷརྨ་བྷ་དྲ། | H20: སངས་རྒྱས་རྣམ་པར་སྣང་མཛད་ཀྱིས་གསུངས་པ་འཕགས་མ་སྒྲོལ་མ་ལ་བསྟོད་པ་ཕྱག་འཚལ་བ་ཉི་ཤུ་རྩ་གཅིག
A21: སློབ་གྲྭ་ཁག་གི་སྔ་དགོང་ཞལ་འདོན། | B21: RCD486DE1 རྗེ་བཙུན་སྒྲོལ་མའི་བསྟོད་པ་ཉི་ཤུ་རྩ་གཅིག་གི་ཚིག་དོན་རྣམ་པར་འགྲེལ་བ།། | C21: RCD486DE1 རྗེ་བཙུན་སྒྲོལ་མའི་བསྟོད་པ་ཉི་ཤུ་རྩ་གཅིག་གི་ཚིག་དོན་རྣམ་པར་འགྲེལ་བ་དད་བརྩོན་བྱང་ཆུབ་སེམས་མཆོག་གི་པདྨའི་གཞོན་ནུ་ཁ་འབྱེད་པའི་ཐབས་ཤེས་ཉི་ཟླའི་འཛུམ་རླབས་ཞེས་བྱ་བཞུགས་སོ།-Segmentation | D21: འགྲེལ་བ། {ཡི་གེ} | G21: =authors!A28 -> དཔལ་ལྡན་ཤེས་རབ། | H21: རྗེ་བཙུན་སྒྲོལ་མའི་བསྟོད་པ་ཉི་ཤུ་རྩ་གཅིག་གི་ཚིག་དོན་རྣམ་པར་འགྲེལ་བ་དད་བརྩོན་བྱང་ཆུབ་སེམས་མཆོག་གི་པདྨའི་གཞོན་ནུ་ཁ་འབྱེད་པའི་ཐབས་ཤེས་ཉི་ཟླའི་འཛུམ་རླབས་ཞེས་བྱ་བཞུགས་སོ། | K21: https://www.padmasambhava.org/wp-content/uploads/PDF/kps_volume1.pdf
A22: སློབ་གྲྭ་ཁག་གི་སྔ་དགོང་ཞལ་འདོན། | B22: R49348A41 རྗེ་བཙུན་མ་འཕགས་མ་སྒྲོལ་མ་ཉི་ཤུ་རྩ་གཅིག་གི་ཚིག་འགྲེལ་དང་དམིགས་རིམ་ཉུང་ངུར་བཀོད་པ་འཕགས་མའི་བྱིན་རླབས་གྲུ་ཆར་བཞུགས།། །། | C22: R49348A41 རྗེ་བཙུན་མ་འཕགས་མ་སྒྲོལ་མ་ཉི་ཤུ་རྩ་གཅིག་གི་ཚིག་འགྲེལ་དང་དམིགས་རིམ་ཉུང་ངུར་བཀོད་པ་འཕགས་མའི་བྱིན་རླབས་གྲུ་ཆར་བཞུགས།།-Segmentation | D22: འགྲེལ་བ། {ཡི་གེ} | G22: སངས་རྒྱས་མཉན་སྤྲུལ། | H22: རྗེ་བཙུན་མ་འཕགས་མ་སྒྲོལ་མ་ཉི་ཤུ་རྩ་གཅིག་གི་ཚིག་འགྲེལ་དང་དམིགས་རིམ་ཉུང་ངུར་བཀོད་པ་འཕགས་མའི་བྱིན་རླབས་གྲུ་ཆར་བཞུགས།། །། | K22: https://dharmacloud.tsadra.org/pdf-reader/?pdf_url=/wp-content/uploads/PDFs_2021/BEN-LB-007.pdf
A23: སློབ་གྲྭ་ཁག་གི་སྔ་དགོང་ཞལ་འདོན། | B23: RAAFE013A ཕྱག་འཚལ་སྒྲོལ་མ་ཉེར་གཅིག་གི་བསྟོད་པའི་བསྡུས་འགྲེལ། | C23: RAAFE013A ཕྱག་འཚལ་སྒྲོལ་མ་ཉེར་གཅིག་གི་བསྟོད་པའི་བསྡུས་འགྲེལ།-Segmentation | D23: འགྲེལ་བ། {ཡི་གེ} | G23: =authors!A80 -> སངས་རྒྱས་མཉན་སྤྲུལ། | H23: ཕྱག་འཚལ་སྒྲོལ་མ་ཉེར་གཅིག་གི་བསྟོད་པའི་བསྡུས་འགྲེལ། | K23: http://purl.bdrc.io/resource/WA0XL10E024BE73B5
A24: སློབ་གྲྭ་ཁག་གི་སྔ་དགོང་ཞལ་འདོན། | B24: R1B1817B6 ཡང་དག་པ་རྫོགས་པའི་སངས་རྒྱས་རྣམ་པར་སྣང་མཛད་ཀྱིས་གསུངས་པ་འཕགས་མ་སྒྲོལ་མ་ལ་བསྟོད་པ་ཕྱག་འཚལ་བ་ཉི་ཤུ་རྩ་གཅིག ། | C24: R1B1817B6 ཡང་དག་པ་རྫོགས་པའི་སངས་རྒྱས་རྣམ་པར་སྣང་མཛད་ཀྱིས་གསུངས་པ་འཕགས་མ་སྒྲོལ་མ་ལ་བསྟོད་པ་ཕྱག་འཚལ་བ་ཉི་ཤུ་རྩ་གཅིག ། Segmentation | D24: འགྲེལ་བ། {ཡི་གེ} | G24: =authors!A25 -> དངུལ་ཆུ་དྷརྨ་བྷ་དྲ། | H24: ཡང་དག་པ་རྫོགས་པའི་སངས་རྒྱས་རྣམ་པར་སྣང་མཛད་ཀྱིས་གསུངས་པ་འཕགས་མ་སྒྲོལ་མ་ལ་བསྟོད་པ་ཕྱག་འཚལ་བ་ཉི་ཤུ་རྩ་གཅིག ། | K24: https://bo.wikipedia.org/wiki/%E0%BD%A6%E0%BE%92%E0%BE%B2%E0%BD%BC%E0%BD%A3%E0%BC%8B%E0%BD%98%E0%BC%8B%E0%BD%89%E0%BD%BA%E0%BD%A2%E0%BC%8B%E0%BD%82%E0%BD%85%E0%BD%B2%E0%BD%82%E0%BC%8B%E0%BD%91%E0%BD%84%E0%BC%8B%E0%BD%A0%E0%BD%82%E0%BE%B2%E0%BD%BA%E0%BD%A3%E0%BC%8B%E0%BD%96%E0%BD%A4%E0%BD%91
A25: སློབ་གྲྭ་ཁག་གི་སྔ་དགོང་ཞལ་འདོན། | B25: RA706B3B9 ཕྱག་འཚལ་སྒྲོལ་མ་ཉེར་གཅིག་མའི་རྣམ་བཤད།༼ཤ༽ | C25: RA706B3B9 ཕྱག་འཚལ་སྒྲོལ་མ་ཉེར་གཅིག་མའི་རྣམ་བཤད།༼ཤ༽ -Segmentation | D25: འགྲེལ་བ། {ཡི་གེ} | G25: =authors!A17 -> ཏཱ་ལའི་བླ་མ ༠༢་དགེ་འདུན་རྒྱ་མཚོ། | H25: ཕྱག་འཚལ་སྒྲོལ་མ་ཉེར་གཅིག་མའི་རྣམ་བཤད།༼ཤ༽ | K25: http://purl.bdrc.io/resource/WA0XL24186DA2B9FA
A26: སློབ་གྲྭ་ཁག་གི་སྔ་དགོང་ཞལ་འདོན། | B26: R83354184 ༄༅། ། ཕྱག་འཚལ་ཉེར་གཅིག་མའི་ཊིཀྐ་འཕགས་མའི་ཞལ་ལུང་ཞེས་བྱ་བ་བཞུགས་སོ། ། | C26: R83354184༄༅། ། ཕྱག་འཚལ་ཉེར་གཅིག་མའི་ཊིཀྐ་འཕགས་མའི་ཞལ་ལུང་ཞེས་བྱ་བ་བཞུགས་སོ། -Segmentation | D26: འགྲེལ་བ། {ཡི་གེ} | G26: =authors!A3 -> ༧དཀོན་མཆོག་ཐབས་མཁས། | H26: ཕྱག་འཚལ་ཉེར་གཅིག་མའི་ཊིཀྐ་འཕགས་མའི་ཞལ་ལུང་ཞེས་བྱ་བ་བཞུགས་སོ། ། | K26: https://library.bdrc.io/show/bdr:MW1NLM4366_O1NLM4366_002?s=%2Fshow%2Fbdr%3AMW1NLM4366%3Fpart%3Dbdr%3AMW1NLM4366_O1NLM4366_002%26s%3Dq%253D%252522%2525E0%2525BC%252584%2525E0%2525BC%252585%2525E0%2525BC%25258D%252520%2525E0%2525BC%25258D%252520%2525E0%2525BD%252595%2525E0%2525BE%2525B1%2525E0%2525BD%252582%2525E0%2525BC%25258B%2525E0%2525BD%2525A0%2525E0%2525BD%25259A%2525E0%2525BD%2525A3%2525E0%2525BC%25258B%2525E0%2525BD%252589%2525E0%2525BD%2525BA%2525E0%2525BD%2525A2%2525E0%2525BC%25258B%2525E0%2525BD%252582%2525E0%2525BD%252585%2525E0%2525BD%2525B2%2525E0%2525BD%252582%2525E0%2525BC%25258B%2525E0%2525BD%252598%2525E0%2525BD%2525A0%2525E0%2525BD%2525B2%2525E0%2525BC%25258B%2525E0%2525BD%25258A%2525E0%2525BD%2525B2%2525E0%2525BD%252580%2525E0%2525BE%252590%2525E0%2525BC%25258B%2525E0%2525BD%2525A0%2525E0%2525BD%252595%2525E0%2525BD%252582%2525E0%2525BD%2525A6%2525E0%2525BC%25258B%2525E0%2525BD%252598%2525E0%2525BD%2525A0%2525E0%2525BD%2525B2%2525E0%2525BC%25258B%2525E0%2525BD%25259E%2525E0%2525BD%2525A3%2525E0%2525BC%25258B%2525E0%2525BD%2525A3%2525E0%2525BD%2525B4%2525E0%2525BD%252584%2525E0%2525BC%25258B%2525E0%2525BD%25259E%2525E0%2525BD%2525BA%2525E0%2525BD%2525A6%2525E0%2525BC%25258B%2525E0%2525BD%252596%2525E0%2525BE%2525B1%2525E0%2525BC%25258B%2525E0%2525BD%252596%2525E0%2525BC%25258B%2525E0%2525BD%252596%2525E0%2525BD%25259E%2525E0%2525BD%2525B4%2525E0%2525BD%252582%2525E0%2525BD%2525A6%2525E0%2525BC%25258B%2525E0%2525BD%2525A6%2525E0%2525BD%2525BC%2525E0%2525BC%25258D%252520%2525E0%2525BC%25258D%252522~1%2526lg%253Dbo%2526t%253DInstance%2526f%253Dasset%252Cinc%252Ctmp%253ApossibleAccess%2526f%253Dasset%252Cinc%252Ctmp%253AcatalogOnly%2526s%253Dclosest%252520matches%252520forced%2526n%253D1#open-viewer
A27: སློབ་གྲྭ་ཁག་གི་སྔ་དགོང་ཞལ་འདོན། | B27: RAC634AC6 ཕྱག་འཚལ་ཉེར་གཅིག་གི་བསྟོད་པའི་རྣམ་པར་བཤད་པ། | C27: RAC634AC6 ཕྱག་འཚལ་ཉེར་གཅིག་གི་བསྟོད་པའི་རྣམ་པར་བཤད་པ། -Segmentation | D27: འགྲེལ་བ། {ཡི་གེ} | G27: =authors!A61 -> རྗེ་བཙུན་ཏཱ་ར་ནཱ་ཐ། | H27: ཕྱག་འཚལ་ཉེར་གཅིག་གི་བསྟོད་པའི་རྣམ་པར་བཤད་པ། | K27: https://dharmacloud.tsadra.org/book/%e0%bd%a6%e0%be%92%e0%be%b2%e0%bd%bc%e0%bd%a3%e0%bc%8b%e0%bd%98%e0%bd%a0%e0%bd%b2%e0%bc%8b%e0%bd%a0%e0%bd%82%e0%be%b2%e0%bd%ba%e0%bd%a3%e0%bc%8b%e0%bd%94%e0%bc%8b%e0%bd%95%e0%be%b1%e0%bd%bc%e0%bd%82-2/
A28: སློབ་གྲྭ་ཁག་གི་སྔ་དགོང་ཞལ་འདོན། | B28: ཤེས་རབ་སྙིང་པོ། | C28: M29C34F4A ཤེས་རབ་སྙིང་པོ། -Segmentation | D28: རྩ་བ། | G28: =authors!A83 -> སྟོན་པ་བཅོམ་ལྡན་འདས། | H28: ཤེས་རབ་ཀྱི་ཕ་རོལ་ཏུ་ཕྱིན་པའི་སྙིང་པོ། | K28: https://library.bdrc.io/show/bdr:WA0RK0529?s=q%3D%2522%25E0%25BD%25A4%25E0%25BD%25BA%25E0%25BD%25A6%25E0%25BC%258B%25E0%25BD%25A2%25E0%25BD%2596%25E0%25BC%258B%25E0%25BD%25A6%25E0%25BE%2599%25E0%25BD%25B2%25E0%25BD%2584%25E0%25BC%258B%25E0%25BD%2594%25E0%25BD%25BC%25E0%25BC%258D%2522~1%26lg%3Dbo%26t%3DWork%26n%3D1
A29: སློབ་གྲྭ་ཁག་གི་སྔ་དགོང་ཞལ་འདོན། | B29: RCDDEF0BE ཤེས་རབ་སྙིང་པོའི་འགྲེལ་བ། | C29: RCDDEF0BE ཤེས་རབ་སྙིང་པོའི་འགྲེལ་བ།-B2-segmentation | D29: འགྲེལ་བ། {ཡི་གེ} | G29: ངག་དབང་ཉི་མ། | H29: ཤེས་རབ་སྙིང་པོའི་འགྲེལ་བ། | K29: http://purl.bdrc.io/resource/WA0XLB18EA1811A74
A30: སློབ་གྲྭ་ཁག་གི་སྔ་དགོང་ཞལ་འདོན། | B30: RCD3C8F1C འཕགས་པ་ཤེས་རབ་ཀྱི་ཕ་རོལ་ཏུ་ཕྱིན་པའི་སྙིང་པོ་རྒྱ་ཆེར་འགྲེལ་པ། | C30: RCD3C8F1C འཕགས་པ་ཤེས་རབ་ཀྱི་ཕ་རོལ་ཏུ་ཕྱིན་པའི་སྙིང་པོ་རྒྱ་ཆེར་འགྲེལ་པ།-segmentation | D30: འགྲེལ་བ། {ཡི་གེ} | G30: =authors!A36 -> པྲ་ཤཱ་སྟྲ་སེ། | H30: འཕགས་པ་ཤེས་རབ་ཀྱི་ཕ་རོལ་ཏུ་ཕྱིན་པའི་སྙིང་པོ་རྒྱ་ཆེར་འགྲེལ་པ། | K30: http://purl.bdrc.io/resource/WA0RT3166
A31: སློབ་གྲྭ་ཁག་གི་སྔ་དགོང་ཞལ་འདོན། | B31: RB76B7B48 ཤེར་ཕྱིན་སྙིང་པོའི་མདོའི་ཚིག་འགྲེལ་རྨད་དུ་བྱུང་བ་བཞུགས། | C31: RB76B7B48 ཤེར་ཕྱིན་སྙིང་པོའི་མདོའི་ཚིག་འགྲེལ་རྨད་དུ་བྱུང་བ་བཞུགས། -Segmentation | D31: འགྲེལ་བ། {ཡི་གེ} | G31: =authors!A61 -> རྗེ་བཙུན་ཏཱ་ར་ནཱ་ཐ། | H31: ཤེར་ཕྱིན་སྙིང་པོའི་མདོའི་ཚིག་འགྲེལ་རྨད་དུ་བྱུང་བ་བཞུགས། | K31: http://purl.bdrc.io/resource/WA1KG5816
A32: སློབ་གྲྭ་ཁག་གི་སྔ་དགོང་ཞལ་འདོན། | B32: RA88988D0 བཅོམ་ལྡན་འདས་མ་ཤེས་རབ་ཀྱི་ཕ་རོལ་ཏུ་ཕྱིན་པའི་སྙིང་པོའི་འགྲེལ་པ་དོན་གྱི་སྒྲོན་མ། | C32: RA88988D0 བཅོམ་ལྡན་འདས་མ་ཤེས་རབ་ཀྱི་ཕ་རོལ་ཏུ་ཕྱིན་པའི་སྙིང་པོའི་འགྲེལ་པ་དོན་གྱི་སྒྲོན་མ།- ཡིག་རྐྱང་རྩེ་ཕུད། (Best E-text)-Segmentation | D32: འགྲེལ་བ། {ཡི་གེ} | G32: ཕྱག་ན་རྡོ་རྗེ། | H32: བཅོམ་ལྡན་འདས་མ་ཤེས་རབ་ཀྱི་ཕ་རོལ་ཏུ་ཕྱིན་པའི་སྙིང་པོའི་འགྲེལ་པ་དོན་གྱི་སྒྲོན་མ། | K32: http://purl.bdrc.io/resource/WA0RT3165
A33: སློབ་གྲྭ་ཁག་གི་སྔ་དགོང་ཞལ་འདོན། | B33: R429207AA འཕགས་པ་ཤེས་རབ་ཀྱི་ཕ་རོལ་ཏུ་ཕྱིན་པའི་སྙིང་པོའི་རྒྱ་ཆེར་བཤད་པ། | C33: R429207AA འཕགས་པ་ཤེས་རབ་ཀྱི་ཕ་རོལ་ཏུ་ཕྱིན་པའི་སྙིང་པོའི་རྒྱ་ཆེར་བཤད་པ། - B7 -Segmentation | D33: འགྲེལ་བ། {ཡི་གེ} | G33: =authors!A33 -> པཎ་ཆེན་དྲི་མེད་བཤེས་གཉེན། | H33: འཕགས་པ་ཤེས་རབ་ཀྱི་ཕ་རོལ་ཏུ་ཕྱིན་པའི་སྙིང་པོའི་རྒྱ་ཆེར་བཤད་པ། | K33: http://purl.bdrc.io/resource/WA0RT3163
A34: སློབ་གྲྭ་ཁག་གི་སྔ་དགོང་ཞལ་འདོན། | B34: R93128D03 ཤེར་སྙིང་རྣམ་བཤད་ཡུམ་དོན་རབ་གསལ། | C34: R93128D03 ཤེར་སྙིང་རྣམ་བཤད་ཡུམ་དོན་རབ་གསལ།-Segmentation | D34: འགྲེལ་བ། {ཡི་གེ} | G34: =authors!A69 -> རོང་སྟོན་ཤེས་བྱ་ཀུན་རིག | H34: ཤེར་སྙིང་རྣམ་བཤད་ཡུམ་དོན་རབ་གསལ། | K34: https://library.bdrc.io/show/bdr:MW28942_5219E7
A35: སློབ་གྲྭ་ཁག་གི་སྔ་དགོང་ཞལ་འདོན། | B35: R73677AF7 ཤེར་རབ་སྙིང་པོའི་རྣམ་བཤད་ཟབ་མོའི་དེ་ཁོ་ན་ཉིད་གསལ་བར་བྱེད་པའི་ཉི་མ། | C35: R73677AF7 ཤེར་རབ་སྙིང་པོའི་རྣམ་བཤད་ཟབ་མོའི་དེ་ཁོ་ན་ཉིད་གསལ་བར་བྱེད་པའི་ཉི་མ།-Segmentation | D35: འགྲེལ་བ། {ཡི་གེ} | G35: =authors!A12 -> ཅོ་ནེ་གྲགས་པ་བཤད་སྒྲུབ། | H35: ཤེར་རབ་སྙིང་པོའི་རྣམ་བཤད་ཟབ་མོའི་དེ་ཁོ་ན་ཉིད་གསལ་བར་བྱེད་པའི་ཉི་མ། | K35: http://purl.bdrc.io/resource/WA0XLB01FCA67F626
A36: སློབ་གྲྭ་ཁག་གི་སྔ་དགོང་ཞལ་འདོན། | B36: R64282E1A ཤེར་སྙིང་འགྲེལ་པ་སྔགས་སུ་བཀྲལ་པ། | C36: R64282E1A ཤེར་སྙིང་འགྲེལ་པ་སྔགས་སུ་བཀྲལ་པ། B-3-Segmentation | D36: འགྲེལ་བ། {ཡི་གེ} | G36: =authors!A73 -> ལོ་ཆེན་བཻ་རོ་ཙ་ན། | H36: ཤེར་སྙིང་འགྲེལ་པ་སྔགས་སུ་བཀྲལ་པ། | K36: http://purl.bdrc.io/resource/WA0XLEABEC8EFB500
A37: སློབ་གྲྭ་ཁག་གི་སྔ་དགོང་ཞལ་འདོན། | B37: R49197A93 ཤེས་རབ་སྙིང་པོའི་མདོའི་ས་བཅད་བཞུགས། | C37: R49197A93 ཤེས་རབ་སྙིང་པོའི་མདོའི་ས་བཅད་བཞུགས། B-2-Segmentation | D37: འགྲེལ་བ། {ཡི་གེ} | G37: =authors!A66 -> རྫ་དཔལ་སྤྲུལ་ཨོ་རྒྱན་འཇིགས་མེད་ཆོས་ཀྱི་དབང་པོ། | H37: སྡོམ་གསུམ་རྣམ་ངེས། སྤྱོད་འཇུག་དང་ཤེར་སྙིང་བཅས་ཀྱི་ས་བཅད། | K37: http://purl.bdrc.io/resource/WA8LS16587
A38: སློབ་གྲྭ་ཁག་གི་སྔ་དགོང་ཞལ་འདོན། | B38: R799C7389 ཤེས་རབ་སྙིང་པོའི་སྐོར་དང་དེའི་བཀའ་ཁྲིད། | C38: R799C7389 ཤེས་རབ་སྙིང་པོའི་སྐོར་དང་དེའི་བཀའ་ཁྲིད།-Segmentation | D38: འགྲེལ་བ། {ཡི་གེ} | G38: =authors!A86 -> ཟམ་གདོང་རིན་པོ་ཆེ། | H38: ཤེས་རབ་སྙིང་པོའི་སྐོར་དང་དེའི་བཀའ་ཁྲིད། | K38: https://samdhongrinpoche.com/%E0%BC%88-%E0%BD%96%E0%BD%85%E0%BD%BC%E0%BD%98%E0%BC%8B%E0%BD%A3%E0%BE%A1%E0%BD%93%E0%BC%8B%E0%BD%A0%E0%BD%91%E0%BD%A6%E0%BC%8B%E0%BD%98%E0%BC%8B%E0%BD%A4%E0%BD%BA%E0%BD%A6%E0%BC%8B%E0%BD%A2%E0%BD%96/
A39: སློབ་གྲྭ་ཁག་གི་སྔ་དགོང་ཞལ་འདོན། | B39: R16A6BB62 ཤེས་རབ་སྙིང་པོའི་འགྲེལ་པ་ཟབ་དོན་གསལ་བའི་སྒྲོན་མེ། | C39: R16A6BB62 ཤེས་རབ་སྙིང་པོའི་འགྲེལ་པ་ཟབ་དོན་གསལ་བའི་སྒྲོན་མེ།-Segmentation | D39: འགྲེལ་བ། {ཡི་གེ} | G39: =authors!A41 -> བྲག་དཀར་སྤྲུལ་སྐུ་བློ་བཟང་དཔལ་ལྡན་བསྟན་འཛིན་སྙན་གྲགས། | H39: ཤེས་རབ་སྙིང་པོའི་འགྲེལ་པ་ཟབ་དོན་གསལ་བའི་སྒྲོན་མེ། | K39: http://purl.bdrc.io/resource/WA0XL472E9FF7FA94
A40: སློབ་གྲྭ་ཁག་གི་སྔ་དགོང་ཞལ་འདོན། | B40: R4D2984CC ཤེས་རབ་སྙིང་པོའི་འགྲེལ་པ་དོན་གསལ་ནོར་བུའི་འོད། | C40: R4D2984CC ཤེས་རབ་སྙིང་པོའི་འགྲེལ་པ་དོན་གསལ་ནོར་བུའི་འོད།-Segmentation | D40: འགྲེལ་བ། {ཡི་གེ} | G40: =authors!A98 -> ཨ་ལག་ཤ་བསྟན་དར། | H40: ཤེས་རབ་སྙིང་པོའི་འགྲེལ་པ་དོན་གསལ་ནོར་བུའི་འོད། | K40: http://purl.bdrc.io/resource/WA7303
...

Sheet Dzongsar
H1: Alignments of RT & C and Langauges | J1: Annotations
B2: ཡིག་རྐྱང་གཙང་མ། | C2: ས་བཅད། | D2: Sentences-Segm | E2: Verse-Segn | F2: Citation | G2: ཚིག་ཕྲེང་དུམ་བུའི་ཁུངས། | H2: རྩ་བ། | I2: འགྲེལ་བ། | K2: མཚན་བྱང་། | L2: མཛད་པ་པོ།
A3: Metadata | B3: Clean Text | C3: Table of Content | G3: Segment Source | H3: Root text | I3: commantary / Other Langauges | K3: Title | L3: Author name
A4: Google doc Link | D4: Google Linkd | I4: Google doc Link
A5: རྡོ་རྗེ་གཅོད་པ།
A7: M42AE7A72 རྡོ་རྗེ་གཅོད་པ་རྩ་བ། -Sanskrit Metadata | G7: རྩ་བ། Sanskrit Tsawa Align | H7: M42AE7A72 རྡོ་རྗེ་གཅོད་པ་རྩ་བ། Tibetan-Sanskrit | I7: M42AE7A72 རྡོ་རྗེ་གཅོད་པ་རྩ་བ། Sanskrit- Tibetan | J7: Sanskrit Alignments | K7: རྡོ་རྗེ་གཅོད་པ། | L7: སྟོན་པ་བཅོམ་ལྡན་འདས།
G8: རྩ་བ། Chinese Tsawa Align | H8: M42AE7A72 རྡོ་རྗེ་གཅོད་པ་རྩ་བ། Tibetan - Chinese | I8: M42AE7A72 金剛般若波羅蜜經 - Chinese-Tibetan Tsawa | K8: རྡོ་རྗེ་གཅོད་པ། | L8: སྟོན་པ་བཅོམ་ལྡན་འདས།
A9: M42AE7A72 རྡོ་རྗེ་གཅོད་པ། Metadata.xlsx | B9: M42AE7A72 རྡོ་རྗེ་གཅོད་པ་རྩ་བ། Clean Root text | G9: རྩ་བ། | H9: M42AE7A72 རྡོ་རྗེ་གཅོད་པ་རྩ་བ། Tsadel | J9: Tsawa | K9: རྡོ་རྗེ་གཅོད་པ། | L9: སྟོན་པ་བཅོམ་ལྡན་འདས།
A10: RF67A9A4E རྡོ་རྗེ་གཅོད་པའི་དོན་བདུན་གྱི་རྒྱ་ཆེར་འགྲེལ་པ། Metadata | B10: RF67A9A4E རྡོ་རྗེ་གཅོད་པའི་དོན་བདུན་གྱི་རྒྱ་ཆེར་འགྲེལ་པ། - Clean text | C10: RF67A9A4E རྡོ་རྗེ་གཅོད་པའི་དོན་བདུན་གྱི་རྒྱ་ཆེར་འགྲེལ་པ། - TOC | D10: RF67A9A4E རྡོ་རྗེ་གཅོད་པའི་དོན་བདུན་གྱི་རྒྱ་ཆེར་འགྲེལ་པ། - Sentence Segm | F10: RF67A9A4E རྡོ་རྗེ་གཅོད་པའི་དོན་བདུན་གྱི་རྒྱ་ཆེར་འགྲེལ་པ། - Citation | G10: འགྲེལ་བ། {ཡི་གེ} | H10: RF67A9A4E རྡོ་རྗེ་གཅོད་པ་རྩ་བ། - Root text Tsadrel | I10: RF67A9A4E རྡོ་རྗེ་གཅོད་པའི་དོན་བདུན་གྱི་རྒྱ་ཆེར་འགྲེལ་པ། - Tsadrel | K10: རྡོ་རྗེ་གཅོད་པའི་དོན་བདུན་གྱི་རྒྱ་ཆེར་འགྲེལ་པ། | L10: སློབ་དཔོན་དབྱིག་གཉེན།
A11: R4B9A8FB5 རྗེ་གཅོད་པ་དང་དེའི་འགྲེལ་པ་ཟབ་དོན་གསལ་བའི་ཉི་མ། Metadate | B11: R4B9A8FB5 རྡོ་རྗེ་གཅོད་བའི་འགྲེལ་བ།_ཅོ་ནེ། - Clean Text | C11: R4B9A8FB5 རྡོ་རྗེ་གཅོད་བའི་འགྲེལ་བ།_ཅོ་ནེ། TOC.docx | D11: R4B9A8FB5 རྡོ་རྗེ་གཅོད་བའི་འགྲེལ་བ།_ཅོ་ནེ། Sentence - Segm | F11: R4B9A8FB5 རྡོ་རྗེ་གཅོད་བའི་འགྲེལ་བ།_ཅོ་ནེ། -Citation | G11: འགྲེལ་བ། {ཡི་གེ} | H11: R4B9A8FB5 རྡོ་རྗེ་གཅོད་པ་རྩ་བ། - Root text Tsadrel | I11: R4B9A8FB5 རྡོ་རྗེ་གཅོད་བའི་འགྲེལ་བ།_ཅོ་ནེ། - Tsadrel | K11: རྡོ་རྗེ་གཅོད་བའི་འགྲེལ་བ།_ཅོ་ནེ། | L11: ཅོ་ནེ་གྲགས་པ་བཤད་སྒྲུབ།
A12: RF161D626 རྡོ་རྗེ་གཅོད་པའི་རྒྱ་ཆེར་འགྲེལ་པ། - Metadata.xlsx | B12: RF161D626 རྡོ་རྗེ་གཅོད་པའི་རྒྱ་ཆེར་འགྲེལ་པ། - Clean Text | C12: RF161D626 རྡོ་རྗེ་གཅོད་པའི་རྒྱ་ཆེར་འགྲེལ་པ། - TOC | D12: RF161D626 རྡོ་རྗེ་གཅོད་པའི་རྒྱ་ཆེར་འགྲེལ་པ། - Sentence-Segm | G12: འགྲེལ་བ། {ཡི་གེ} | H12: RF161D626 རྡོ་རྗེ་གཅོད་པ་རྩ་བ། - Root text Tsadrel | I12: RF161D626 རྡོ་རྗེ་གཅོད་པའི་རྒྱ་ཆེར་འགྲེལ་པ། - Tsadrel | K12: རྡོ་རྗེ་གཅོད་པའི་རྒྱ་ཆེར་འགྲེལ་པ། | L12: ཀ་མ་ལ་ཤཱི་ལ།
I13: R3452D71B རྡོ་རྗེ་གཅོད་པའི་བསྡུས་དོན་འགྲེལ་པ་ཀ་མ་ལ་ཤཱི་ལའི་ཞལ་ལུང་བཞོགས་སོ།
I14: R76E83977 རྡོ་རྗེ་གཅོད་པའི་ཕན་ཡོན། - B2
A16: MFF4994FD金剛波羅蜜經 Metadata.xlsx | G16: རྩ་བ།
A17: R434373A0金剛般若波羅蜜經論 Metadata | G17: འགྲེལ་བ། {ཡི་གེ} | H17: R434373A0金剛波羅蜜經 Root text Tsadrel | I17: R434373A0金剛般若波羅蜜經論 - Commentary Tsadrel Alignment | L17: 釋迦佛
A18: R2A8AD21D金剛經解義 | G18: འགྲེལ་བ། {ཡི་གེ} | H18: R2A8AD21D金剛般若波羅蜜經 - Root text Tsadrel | I18: R2A8AD21D金剛經解義-Commentary Tsadrel Alignment | L18: 天親/Vasubandhu/སློབ་དཔོན་དབྱིག་གཉེན།
A19: RAF408FDA 金剛般若經贊述- Metadata.xlsx.xlsx | G19: འགྲེལ་བ། {ཡི་གེ} | H19: RAF408FDA 金剛波羅蜜經 - Root text Tsadrel | I19: RAF408FDA 金剛般若經贊述 - Commentary Tsadrel Alignment | L19: 唐 慧能說
A20: R92439761 金剛般若波羅蜜經義脈.xlsx | G20: འགྲེལ་བ། {ཡི་གེ} | H20: R92439761 金剛般若波羅蜜經- Root text Tsadrel | I20: R92439761 金剛般若波羅蜜經義脈.docx | L20: 唐 窺基撰
A21: R96396549金剛般若波羅蜜經註解 | H21: R96396549金剛般若波羅蜜經- Root text Tsadrel | I21: R96396549金剛般若波羅蜜經註解 - Commentary Tsadrel Alignment | L21: 金剛般若波羅蜜經註解
L22: 太虛大師
A26: ཤེས་རབ་སྙིང་པོ།
A28: M29C34F4A ཤེས་རབ་སྙིང་པོ། Metadata | B28: M29C34F4A ཤེས་རབ་སྙིང་པོ། - Clean text Tsawa | D28: M29C34F4A ཤེས་རབ་སྙིང་པོ། -Segmentation | G28: རྩ་བ། Sanskrit Tsawa Align | H28: M29C34F4A ཤེས་རབ་སྙིང་པོ། Tibetan- Sanskrit | I28: M29C34F4A ཤེས་རབ་སྙིང་པོ། Sanskrit-Tsawa Align | J28: Tsawa and Sanskrit Alignment | K28: ཤེས་རབ་ཀྱི་ཕ་རོལ་ཏུ་ཕྱིན་པའི་སྙིང་པོ། | L28: སྟོན་པ་བཅོམ་ལྡན་འདས། | N28: https://www.dsbcproject.org/canon-text/content/401/1829 | O28: https://www.dsbcproject.org/canon-text/content/400/1828
G29: རྩ་བ། Chinese Tsawa Align | H29: M29C34F4A ཤེས་རབ་སྙིང་པོ། Tibetan-Chinese | I29: M29C34F4A ཤེས་རབ་སྙིང་པོ། 心經 Chinese -Tibetan
A30: R64282E1A ཤེར་སྙིང་འགྲེལ་པ་སྔགས་སུ་བཀྲལ་པ། - Metadata | B30: R64282E1A ཤེར་སྙིང་འགྲེལ་པ་སྔགས་སུ་བཀྲལ་པ། - Clean text | C30: R64282E1A ཤེར་སྙིང་འགྲེལ་པ་སྔགས་སུ་བཀྲལ་པ། - TOC | D30: R64282E1A ཤེར་སྙིང་འགྲེལ་པ་སྔགས་སུ་བཀྲལ་པ། - Sentence - Segm | F30: R64282E1A ཤེར་སྙིང་འགྲེལ་པ་སྔགས་སུ་བཀྲལ་པ། - Citation | G30: འགྲེལ་བ། {ཡི་གེ} | H30: R64282E1A ཤེས་རབ་སྙིང་པོ། - Root Text Tsadel | I30: R64282E1A ཤེར་སྙིང་འགྲེལ་པ་སྔགས་སུ་བཀྲལ་པ། Tsadel | J30: Commentary alignment | K30: ཤེར་སྙིང་འགྲེལ་པ་སྔགས་སུ་བཀྲལ་པ། | L30: ལོ་ཆེན་བཻ་རོ་ཙ་ན།
A31: RA88988D0 བཅོམ་ལྡན་འདས་མ་ཤེས་རབ་ཀྱི་ཕ་རོལ་ཏུ་ཕྱིན་པའི་སྙིང་པོའི་འགྲེལ་པ་དོན་གྱི་སྒྲོན་མ།- Metadata | B31: RA88988D0 བཅོམ་ལྡན་འདས་མ་ཤེས་རབ་ཀྱི་ཕ་རོལ་ཏུ་ཕྱིན་པའི་སྙིང་པོའི་འགྲེལ་པ་དོན་གྱི་སྒྲོན་མ། - Clean text delwa | C31: RA88988D0 བཅོམ་ལྡན་འདས་མ་ཤེས་རབ་ཀྱི་ཕ་རོལ་ཏུ་ཕྱིན་པའི་སྙིང་པོའི་འགྲེལ་པ་དོན་གྱི་སྒྲོན་མ། - TOC | D31: RA88988D0 བཅོམ་ལྡན་འདས་མ་ཤེས་རབ་ཀྱི་ཕ་རོལ་ཏུ་ཕྱིན་པའི་སྙིང་པོའི་འགྲེལ་པ་དོན་གྱི་སྒྲོན་མ། - Sentence- Segm | G31: འགྲེལ་བ། {ཡི་གེ} | H31: RA88988D0 ཤེས་རབ་སྙིང་པོ། -Root text Tsadel | I31: RA88988D0 བཅོམ་ལྡན་འདས་མ་ཤེས་རབ་ཀྱི་ཕ་རོལ་ཏུ་ཕྱིན་པའི་སྙིང་པོའི་འགྲེལ་པ་དོན་གྱི་སྒྲོན་མ།- ཡིག་རྐྱང་རྩེ་ཕུད། - Tsadeel | J31: Commentary alignment | K31: བཅོམ་ལྡན་འདས་མ་ཤེས་རབ་ཀྱི་ཕ་རོལ་ཏུ་ཕྱིན་པའི་སྙིང་པོའི་འགྲེལ་པ་དོན་གྱི་སྒྲོན་མ། | L31: ཕྱག་ན་རྡོ་རྗེ།
A32: RB76B7B48 ཤེར་ཕྱིན་སྙིང་པོའི་མདོའི་ཚིག་འགྲེལ་རྨད་དུ་བྱུང་བ་བཞུགས། Metadata | B32: RB76B7B48 ཤེར་ཕྱིན་སྙིང་པོའི་མདོའི་ཚིག་འགྲེལ་རྨད་དུ་བྱུང་བ་བཞུགས། -Clean Texts | C32: RB76B7B48 ཤེར་ཕྱིན་སྙིང་པོའི་མདོའི་ཚིག་འགྲེལ་རྨད་དུ་བྱུང་བ་བཞུགས། -TOC | D32: RB76B7B48 ཤེར་ཕྱིན་སྙིང་པོའི་མདོའི་ཚིག་འགྲེལ་རྨད་དུ་བྱུང་བ་བཞུགས། -Sentenc-Segm | F32: RB76B7B48 ཤེར་ཕྱིན་སྙིང་པོའི་མདོའི་ཚིག་འགྲེལ་རྨད་དུ་བྱུང་བ་བཞུགས། -Citation | G32: འགྲེལ་བ། {ཡི་གེ} | H32: RB76B7B48 ཤེས་རབ་སྙིང་པོ། -Root Text Tsadel | I32: RB76B7B48 ཤེར་ཕྱིན་སྙིང་པོའི་མདོའི་ཚིག་འགྲེལ་རྨད་དུ་བྱུང་བ་བཞུགས། -Tsadel | J32: Commentary alignment | K32: ཤེར་ཕྱིན་སྙིང་པོའི་མདོའི་ཚིག་འགྲེལ་རྨད་དུ་བྱུང་བ་བཞུགས། | L32: ཏཱ་ར་ནཱ་ཐ། | M32: Kalsang Gyaltsen/ Lobsang Dhondup/ Yeshi Lhundup | O32: Done
A33: R429207AA འཕགས་པ་ཤེས་རབ་ཀྱི་ཕ་རོལ་ཏུ་ཕྱིན་པའི་སྙིང་པོའི་རྒྱ་ཆེར་བཤད་པ། Metadata | B33: R429207AA འཕགས་པ་ཤེས་རབ་ཀྱི་ཕ་རོལ་ཏུ་ཕྱིན་པའི་སྙིང་པོའི་རྒྱ་ཆེར་བཤད་པ། | D33: R429207AA འཕགས་པ་ཤེས་རབ་ཀྱི་ཕ་རོལ་ཏུ་ཕྱིན་པའི་སྙིང་པོའི་རྒྱ་ཆེར་བཤད་པ། - Sentence-Segm | F33: R429207AA འཕགས་པ་ཤེས་རབ་ཀྱི་ཕ་རོལ་ཏུ་ཕྱིན་པའི་སྙིང་པོའི་རྒྱ་ཆེར་བཤད་པ། -Citation | G33: འགྲེལ་བ། {ཡི་གེ} | H33: R429207AA ཤེས་རབ་སྙིང་པོ། - Clean Root Tsadel | I33: R429207AA འཕགས་པ་ཤེས་རབ་ཀྱི་ཕ་རོལ་ཏུ་ཕྱིན་པའི་སྙིང་པོའི་རྒྱ་ཆེར་བཤད་པ། - Tsadel | J33: Commentary alignment | K33: ཤེར་ཕྱིན་སྙིང་པོའི་རྒྱ་ཆེར་བཤད་པ། | L33: པཎ་ཆེན་དྲི་མེད་བཤེས་གཉེན། རྒྱ་གར། | M33: Lobsang Dhondup and Yeshi Lhundup | N33: =150 -> 150 | O33: Done
A34: RCDDEF0BE ཤེས་རབ་སྙིང་པོའི་འགྲེལ་བ། - Metadata | G34: འགྲེལ་བ། {ཡི་གེ} | H34: RCDDEF0BE ཤེས་རབ་སྙིང་པོའི་འགྲེལ་བ།-Tsawa | I34: RCDDEF0BE ཤེས་རབ་སྙིང་པོའི་འགྲེལ་བ།-Tsadel | J34: Commentary alignment | K34: ཤེས་རབ་སྙིང་པོའི་འགྲེལ་བ། | L34: སྒོ་མང་མཁན་ཟུར་ངག་དབང་ཉི་མ། | Q34: http://purl.bdrc.io/resource/WA0XLB18EA1811A74
A35: RCD3C8F1C འཕགས་པ་ཤེས་རབ་ཀྱི་ཕ་རོལ་ཏུ་ཕྱིན་པའི་སྙིང་པོ་རྒྱ་ཆེར་འགྲེལ་པ། Metadata | G35: འགྲེལ་བ། {ཡི་གེ} | H35: RCD3C8F1C ཤེས་རབ་སྙིང་པོ། - Tsawa | I35: RCD3C8F1C འཕགས་པ་ཤེས་རབ་ཀྱི་ཕ་རོལ་ཏུ་ཕྱིན་པའི་སྙིང་པོ་རྒྱ་ཆེར་འགྲེལ་པ།- Tsadel | J35: Commentary alignment | K35: འཕགས་པ་ཤེས་རབ་ཀྱི་ཕ་རོལ་ཏུ་ཕྱིན་པའི་སྙིང་པོ་རྒྱ་ཆེར་འགྲེལ་པ། | L35: པྲ་ཤཱ་སྟྲ་སེ། རྒྱ་གར། | Q35: http://purl.bdrc.io/resource/WA0RT3166
A36: R42066499ཤེས་རབ་སྙིང་པོའི་རྣམ་བཤད། | G36: འགྲེལ་བ། {ཡི་གེ} | H36: R42066499 ཤེས་རབ་སྙིང་པོའི་རྣམ་བཤད། -Tsawa | I36: R42066499 ཤེས་རབ་སྙིང་པོའི་རྣམ་བཤད། -Tsadel | J36: Commentary alignment | K36: གཞུང་མཆོག་ཤེས་རབ་སྙིང་པོའི་རྣམ་བཤད་ཟབ་དོན་པད་དཀར་བཞད་པའི་ཉིན་བྱེད། | L36: གཙོས་ཁྲི་སྤྲུལ ༠༢་བློ་བཟང་རྒྱལ་མཚན་སེངྒེ། | Q36: https://library.bdrc.io/show/bdr:WA0RK0529?s=q%3D%2522%25E0%25BD%25A4%25E0%25BD%25BA%25E0%25BD%25A6%25E0%25BC%258B%25E0%25BD%25A2%25E0%25BD%2596%25E0%25BC%258B%25E0%25BD%25A6%25E0%25BE%2599%25E0%25BD%25B2%25E0%25BD%2584%25E0%25BC%258B%25E0%25BD%2594%25E0%25BD%25BC%25E0%25BC%258D%2522~1%26lg%3Dbo%26t%3DWork%26n%3D1
A37: RA7B8FF79 ཤེས་རབ་སྙིང་པོའི་རྣམ་བཤད་ཡང་དག་ལྟ་བའི་མིག Metadata | G37: འགྲེལ་བ། {ཡི་གེ} | H37: RA7B8FF79 ཤེས་རབ་སྙིང་པོའི་རྣམ་བཤད་ཡང་དག་ལྟ་བའི་མིག -Tsawa | I37: RA7B8FF79 ཤེས་རབ་སྙིང་པོའི་རྣམ་བཤད་ཡང་དག་ལྟ་བའི་མིག -Tsadel | J37: Commentary alignment | K37: ཤེས་རབ་སྙིང་པོའི་རྣམ་བཤད་ཡང་དག་ལྟ་བའི་མིག | L37: དགེ་འདུན་རིན་ཆེན། | Q37: http://purl.bdrc.io/resource/WA0XL29B7CCC47F6B
A38: RA25D53E9 འཕྲ་ཏིག་དང་པོ། ཤེས་རབ་སྙིང་པོའི་བཤད་འབུམ། Metadata | G38: འགྲེལ་བ། {ཡི་གེ} | H38: RA25D53E9 འཕྲ་ཏིག་དང་པོ། ཤེས་རབ་སྙིང་པོའི་བཤད་འབུམ།-Tsawa | I38: RA25D53E9 འཕྲ་ཏིག་དང་པོ། ཤེས་རབ་སྙིང་པོའི་བཤད་འབུམ།-Tsadel | J38: Commentary alignment | K38: འཕྲ་ཏིག་དང་པོ། ཤེས་རབ་སྙིང་པོའི་བཤད་འབུམ། | L38: བླ་མ་ཀུན་དགའ། | Q38: http://purl.bdrc.io/resource/WA0XLBA22F3396909
A40: འཕགས་སྡུད།
A42: འཕགས་པ་སྡུད་པ། - Metadata | B42: འཕགས་པ་སྡུད་པ། - Clean root Text | E42: འཕགས་པ་ཤེས་རབ་ཀྱི་ཕ་རོལ་ཏུ་ཕྱིན་པ་སྡུད་པའི་ཚིགས་སུ་བཅད་པ། -Sentence- Segm | G42: རྩ་བ། Sanskrit Tsawa Align | H42: M6BD866B7 འཕགས་པ་སྡུད་པ། - Clean Tsawa | J42: Tsawa and Sanskrit Alignment | K42: འཕགས་པ་སྡུད་པ། | L42: སྟོན་པ་བཅོམ་ལྡན་འདས།
G43: རྩ་བ། Chinese Tsawa Align | H43: M6BD866B7 འཕགས་སྡུད།Tibetan-Chinese Tsawa | I43: M6BD866B7 འཕགས་པ་སྡུད་པ། Chinese-Tibetan Tsawa | J43: Tsawa and Chinese Alignment | K43: འཕགས་པ་སྡུད་པ། | L43: སྟོན་པ་བཅོམ་ལྡན་འདས།
G44: རྩ་བ། Sanskrit Tsawa Align | H44: M6BD866B7 འཕགས་པ་སྡུད་པ། Tibetan - Sanskrit Tsawa | I44: M6BD866B7འཕགས་སྡུད། Sanskrit-Tibetan Tsawa | J44: Tsawa and Sanskrit Alignment | K44: འཕགས་པ་སྡུད་པ། | L44: སྟོན་པ་བཅོམ་ལྡན་འདས།
A45: R79FDDBD3 སྡུད་པ་ཚིགས་སུ་བཅད་པའི་འགྲེལ་པ། - Metadata | B45: R825B644F མདོ་སྡུད་པ་ཚིགས་སུ་བཅད་པའི་འགྲེལ་པ་ཕ་རོལ་ཏུ་ཕྱིན་པའི་རྒྱ་མཚོའི་སྡེ་དང་། མདོ་དང་བསྟན་བཅོས་སྦྱར་ཚུལ་མ་ཕམ་ཞལ་ལུང་། །Clean Text | C45: R79FDDBD3 སྡུད་པ་ཚིགས་སུ་བཅད་པའི་འགྲེལ་པ། - TOC | D45: R79FDDBD3 སྡུད་པ་ཚིགས་སུ་བཅད་པའི་འགྲེལ་པ། Segmentation | F45: R79FDDBD3 སྡུད་པ་ཚིགས་སུ་བཅད་པའི་འགྲེལ་པ། - Citation | G45: འགྲེལ་བ། {ཡི་གེ} | H45: འཕགས་པ་སྡུད་པ། - Clean root Text | I45: R79FDDBD3 སྡུད་པ་ཚིགས་སུ་བཅད་པའི་འགྲེལ་པ། - Tsadel | J45: Commentary Alignments | K45: འཕགས་པ་ཤེས་རབ་ཀྱི་ཕ་རོལ་ཏུ་ཕྱིན་པ་སྡུད་པ་ཚིགས་སུ་བཅད་པའི་ཊཱི་ཀ་ཡིད་བཞིན་གྱི་ནོར་བུ་རིན་པོ་ཆེ་ལྟ་བུ་ཕ་རོལ་ཏུ་ཕྱིན་པ་རྒྱ་མཚོའི་སྡེ་ཞེས་བྱ་བ་བཞུགས་སོ།། | L45: ཀརྨ་མི་བསྐྱོད་རྡོ་རྗེ། | M45: Lobsang Dhondup | N45: =120+420+160+180 -> 880 | O45: Done
A46: R09FD3ABF ཡོན་ཏན་རིན་ཆེན་སྡུད་པའི་འགྲེལ་པ་རྒྱལ་བའི་ཡུམ་གྱི་དགོངས་དོན་ལ་ཕྱིན་ཅི་མ་ལོག་པར་འཇུག་པའི་ལེགས་བཤད་ཅེས་བྱ་བ་བཞུགས།-Metadata | B46: R09FD3ABF ཡོན་ཏན་རིན་ཆེན་སྡུད་པའི་འགྲེལ་པ་རྒྱལ་བའི་ཡུམ་གྱི་དགོངས་དོན་ལ་ཕྱིན་ཅི་མ་ལོག་པར་འཇུག་པའི་ལེགས་བཤད་ཅེས་བྱ་བ་བཞུགས།-Clean text | C46: R09FD3ABF ཡོན་ཏན་རིན་ཆེན་སྡུད་པའི་འགྲེལ་པ་རྒྱལ་བའི་ཡུམ་གྱི་དགོངས་དོན་ལ་ཕྱིན་ཅི་མ་ལོག་པར་འཇུག་པའི་ལེགས་བཤད་ཅེས་བྱ་བ་བཞུགས། TOC | D46: R09FD3ABF ཡོན་ཏན་རིན་ཆེན་སྡུད་པའི་འགྲེལ་པ་རྒྱལ་བའི་ཡུམ་གྱི་དགོངས་དོན་ལ་ཕྱིན་ཅི་མ་ལོག་པར་འཇུག་པའི་ལེགས་བཤད་ཅེས་བྱ་བ་བཞུགས། - Sentence- Segn | G46: འབྲུ་འགྲེལ། | H46: འཕགས་པ་སྡུད་པ། - Clean root Text | I46: R09FD3ABF ཡོན་ཏན་རིན་ཆེན་སྡུད་པའི་འགྲེལ་པ་རྒྱལ་བའི་ཡུམ་གྱི་དགོངས་དོན་ལ་ཕྱིན་ཅི་མ་ལོག་པར་འཇུག་པའི་ལེགས་བཤད་ཅེས་བྱ་བ་བཞུགས། | J46: Commentary Alignments | K46: ཡོན་ཏན་རིན་ཆེན་སྡུད་པའི་འགྲེལ་པ་རྒྱལ་བའི་ཡུམ་གྱི་དགོངས་དོན་ལ་ཕྱིན་ཅི་མ་ལོག་པར་འཇུག་པའི་ལེགས་བཤད་ཅེས་བྱ་བ་བཞུགས་སོ། ། | L46: འཇུ་མི་ཕམ། | M46: kalsang Gyaltsen | N46: =60+60+15+60+5+60+60+60+30+60+35+40 -> 545 | O46: Done
A47: R0804AAA2 ཕགས་པ་མདོ་སྡུད་པའི་འགྲེལ་པ་རྒྱས་པ་སྤས་དོན་གསལ་བའི་སྒྲོན་མེ། - Metadata | B47: R0804AAA2 ཕགས་པ་མདོ་སྡུད་པའི་འགྲེལ་པ་རྒྱས་པ་སྤས་དོན་གསལ་བའི་སྒྲོན་མེ། - Clean Text | C47: R0804AAA2 ཕགས་པ་མདོ་སྡུད་པའི་འགྲེལ་པ་རྒྱས་པ་སྤས་དོན་གསལ་བའི་སྒྲོན་མེ། ས་བཅད། - TOC.docx | D47: R0804AAA2 ཕགས་པ་མདོ་སྡུད་པའི་འགྲེལ་པ་རྒྱས་པ་སྤས་དོན་གསལ་བའི་སྒྲོན་མེ། - Sentence-Segm | F47: R0804AAA2 ཕགས་པ་མདོ་སྡུད་པའི་འགྲེལ་པ་རྒྱས་པ་སྤས་དོན་གསལ་བའི་སྒྲོན་མེ། - Citation | G47: འགྲེལ་བ། {ཡི་གེ} | H47: R0804AAA2 འཕགས་པ་སྡུད་པ། - Root text Tsadrel | I47: R0804AAA2 ཕགས་པ་མདོ་སྡུད་པའི་འགྲེལ་པ་རྒྱས་པ་སྤས་དོན་གསལ་བའི་སྒྲོན་མེ། -Tsadrel | J47: Commentary Alignments | K47: འཕགས་པ་མདོ་སྡུད་པའི་འགྲེལ་པ་རྒྱས་པ་སྤས་དོན་གསལ་བའི་སྒྲོན་མེ། | L47: ཤཱ་ས་ན་དཱི་བཾ།
A48: R7AABAABE ཡོན་ཏན་རིན་པོ་ཆེ་སྡུད་པ་ཚིགས་སུ་བཅད་པའི་འགྲེལ་པ། - Metadata | C48: R7AABAABE ཡོན་ཏན་རིན་པོ་ཆེ་སྡུད་པ་ཚིགས་སུ་བཅད་པའི་འགྲེལ་པ། - Clean Formatted Text with TOC.docx | G48: འགྲེལ་བ། {ཡི་གེ} | H48: R7AABAABE འཕགས་པ་སྡུད་པ། - Root text Tsadrel | I48: R7AABAABE ཡོན་ཏན་རིན་པོ་ཆེ་སྡུད་པ་ཚིགས་སུ་བཅད་པའི་འགྲེལ་པ། - Commentary Tsadrel Alignment | J48: Commentary Alignment | K48: ཡོན་ཏན་རིན་པོ་ཆེ་སྡུད་པ་ཚིགས་སུ་བཅད་པའི་འགྲེལ་པ། | L48: མཁྱེན་རབ་འཇམ་དབྱངས་བློ་བཟང་འཕྲིན་ལས།
...

Sheet Chinese
A1: Category | B1: Main files | C1: Final E-text files | D1: Sentence- Segn E-text link | E1: Type རྒྱུ་ཆའི་རིགས། | F1: Google doc Link | G1: Metadata | H1: མཚན་བྱང་། Title | I1: མཛད་པ་པོ། Author name | J1: Website link བརྩམས་ཆོས་དྲ་ཐག
A2: ནང་པའི་ལྟ་གྲུབ། | B2: MFF4994FD The Diamond Sūtra in Chinese 金剛經 | C2: https://drive.google.com/drive/folders/1IgdWp_ENmSCZMJEn9abtABTalL2rUFiJ | D2: MFF4994FD金剛波羅蜜經 | E2: རྩ་བ། | F2: https://docs.google.com/document/d/1WFgm_fjDCuNeMm5XLn79DU21OtwiBP1bArV9T2PhwIs/edit?tab=t. | H2: 金剛經 | I2: =authors!A4 -> ཀ་མ་ལ་ཤཱི་ལ། | J2: https://cbetaonline.dila.edu.tw/zh/T0235_001
A3: ནང་པའི་ལྟ་གྲུབ། | B3: MFF4994FD The Diamond Sūtra in Chinese 金剛經 | C3: https://drive.google.com/drive/folders/1npDb7_y804AmYqRliwUnhESOW96aZ_VN | D3: R434373A0金剛般若波羅蜜經論 | E3: འགྲེལ་བ། {ཡི་གེ} | F3: https://docs.google.com/document/d/1B7UlbkpSJECu_0zf33ie8tjbE_BF1JZK0cXLeW8tHBE/edit?tab=t.0 | H3: 金剛般若波羅蜜經論 | I3: =authors!A3 -> ༧དཀོན་མཆོག་ཐབས་མཁས། | J3: https://cbetaonline.dila.edu.tw/zh/T1511_001
A4: ནང་པའི་ལྟ་གྲུབ། | B4: MFF4994FD The Diamond Sūtra in Chinese 金剛經 | C4: https://drive.google.com/drive/folders/1HLPBirwRn70PMjpAShrD1Dmx5oPkXye3 | D4: R43644D12金剛般若波羅蜜經論 | E4: འགྲེལ་བ། {ཡི་གེ} | F4: https://drive.google.com/open?id=1SdZj_tFj0-ZeBSbBD20_7-drDBpKm8k_mJy34Tx64k0&usp=drive_copy | H4: 金剛般若波羅蜜經註解 | I4: =authors!A5 -> ཁྲི་ཆེན་སྤྲུལ་སྐུ་བློ་བཟང་བསྟན་པའི་ཉི་མ | J4: https://cbetaonline.dila.edu.tw/zh/T1703_001
A5: ནང་པའི་ལྟ་གྲུབ། | B5: MFF4994FD The Diamond Sūtra in Chinese 金剛經 | C5: https://drive.google.com/drive/folders/1HLPBirwRn70PMjpAShrD1Dmx5oPkXye3 | D5: R96396549金剛般若波羅蜜經註解 | E5: འགྲེལ་བ། {ཡི་གེ} | F5: https://drive.google.com/open?id=1ZftXSL-sWjfwsCZUbquVc1F3FI6D6e69kaghNwifWRA&usp=drive_copy | H5: 金剛般若波羅蜜經註解 | I5: =authors!A5 -> ཁྲི་ཆེན་སྤྲུལ་སྐུ་བློ་བཟང་བསྟན་པའི་ཉི་མ | J5: https://cbetaonline.dila.edu.tw/zh/T1703_001
A6: ནང་པའི་ལྟ་གྲུབ། | B6: MFF4994FD The Diamond Sūtra in Chinese 金剛經 | C6: https://drive.google.com/drive/folders/1R9u-a2AVvakm_MEBlqmiQmZOnaEl8S39 | D6: R2A8AD21D金剛經解義 | E6: འགྲེལ་བ། {ཡི་གེ} | F6: https://docs.google.com/document/d/1WiJm2afsImzvLxk9FxWSwDCjP3W7E-SPpK9BWzK7fGI/edit?tab=t.0 | H6: 金剛經解義 | I6: =authors!A6 -> ཁྲི་བྱང ༠༣་བློ་བཟང་ཡེ་ཤེས་བསྟན་འཛིན་རྒྱ་མཚོ། | J6: https://cbetaonline.dila.edu.tw/zh/X0459_001
A7: ནང་པའི་ལྟ་གྲུབ། | B7: MFF4994FD The Diamond Sūtra in Chinese 金剛經 | C7: https://drive.google.com/drive/folders/1hgWoDXk9FKQgR84fHmzjICsvRFPJe3sR?usp=drive_link | D7: R3E4D8B99金剛經講話 | E7: འགྲེལ་བ། {ཡི་གེ} | F7: https://drive.google.com/open?id=1Wpy0dascVl1DW_qXLnXN4rsLUuXikRy2klWjzIbvJHw&usp=drive_copy | H7: 金剛經講話 | I7: =authors!A7 -> གྲགས་པ་རྒྱལ་མཚན་ | J7: http://www.masterhsingyun.org/article/article.jsp?index=0&item=65&bookid=2c907d49439913c90143a942d86c0066&ch=1&se=0&f=1
A8: ནང་པའི་ལྟ་གྲུབ། | B8: MFF4994FD The Diamond Sūtra in Chinese 金剛經 | C8: https://drive.google.com/drive/folders/1QRwvvg51nWyA1lwM8jc246NFUEIeiGgt | D8: R67954D57金剛般若波羅蜜經破取著不壞假名論 | E8: འགྲེལ་བ། {ཡི་གེ} | F8: https://drive.google.com/open?id=1g6H4n4478ICMhbIzMnHcOX5PDTDg0YhXn0phAvU2mO0&usp=drive_copy | H8: 金剛般若波羅蜜經破取著不壞假名論 | I8: =authors!A8 -> གསེར་ཀོང་ངག་དབང་ཚུལ་ཁྲིམས་དོན་ལྡན། | J8: https://cbetaonline.dila.edu.tw/zh/T25n1515_001
A9: ནང་པའི་ལྟ་གྲུབ། | B9: MFF4994FD The Diamond Sūtra in Chinese 金剛經 | C9: https://drive.google.com/drive/folders/1k7M85YdRFbXHQSILvaJ0cXWAnuO8pnk1?usp=drive_link | D9: R2BF994FF 《金剛經》講記 | E9: འགྲེལ་བ། {ཡི་གེ} | F9: https://drive.google.com/open?id=1ph2BhTInyar809Gp8YanQdcoNTFuzF3Rjkvunfl-KBE&usp=drive_copy | H9: 《金剛經》講記 | I9: =authors!A9 -> ངག་དབང་ཉི་མ། | J9: https://old.ddc.shengyen.org/mobile/toc/07/07-02-1/index.php
A10: ནང་པའི་ལྟ་གྲུབ། | B10: MFF4994FD The Diamond Sūtra in Chinese 金剛經 | C10: https://drive.google.com/drive/folders/1jCBNlqOwkPafmlb21pV8k_WQtJu9cgkx?usp=drive_link | D10: R2FB78325 金剛般若波羅密經講義 | E10: འགྲེལ་བ། {ཡི་གེ} | F10: https://drive.google.com/open?id=1_7qJZEpbXf6ovbkc8WbgA6gdbvghZB0p62mnSmz9cNs&usp=drive_copy | H10: 金剛般若波羅密經講義 | I10: =authors!B10 | J10: http://www.book853.com/show.aspx?id=890&cid=78

Sheet authors
A1: name on Pecha | B1: other name | C1: other name 2
A2: ༸གོང་ས་མཆོག
A3: ༧དཀོན་མཆོག་ཐབས་མཁས། | B3: བསྟན་པ་རྒྱ་མཚོ།
A4: ཀ་མ་ལ་ཤཱི་ལ།
A5: ཁྲི་ཆེན་སྤྲུལ་སྐུ་བློ་བཟང་བསྟན་པའི་ཉི་མ
A6: ཁྲི་བྱང ༠༣་བློ་བཟང་ཡེ་ཤེས་བསྟན་འཛིན་རྒྱ་མཚོ།
A7: གྲགས་པ་རྒྱལ་མཚན་
A8: གསེར་ཀོང་ངག་དབང་ཚུལ་ཁྲིམས་དོན་ལྡན།
A9: ངག་དབང་ཉི་མ།
A10: ངག་དབང་ཕུན་ཚོགས།
A11: ངོར་མཁན་ཆེན ༠༡་ཀུན་དགའ་བཟང་པོ།
A12: ཅོ་ནེ་གྲགས་པ་བཤད་སྒྲུབ།
A13: ཆོས་ཀྱི་རྒྱལ་མཚན།
A14: ཆོས་གྲགས།
A15: ཇོ་བོ་རྗེ་དཔལ་ལྡན་ཨ་ཏི་ཤ | B15: ཇོ་བོ་རྗེ་ | C15: ཨ་ཏི་ཤ | D15: དཔལ་ལྡན་ཨ་ཏི་ཤ | E15: ཨ་ཏི་ཤ།
A16: ཉན་ཤུལ་མཁྱེན་རབ་འོད་གསལ།
A17: ཏཱ་ལའི་བླ་མ ༠༢་དགེ་འདུན་རྒྱ་མཚོ།
A18: ཏཱ་ལའི་བླ་མ ༠༥་ངག་དབང་བློ་བཟང་རྒྱ་མཚོ།
A19: ཏཱ་ལའི་བླ་མ ༡༤་བསྟན་འཛིན་རྒྱ་མཚོ། | B19: ཏཱ་ལའི་བླ་མ ༡༤
A20: ཐུའུ་བཀྭན ༠༣་བློ་བཟང་ཆོས་ཀྱི་ཉི་མ།
A21: དཀའ་ཆེན་པདྨ།
A22: དཀོན་མཆོག་བསྟན་པའི་སྒྲོན་མེ།
A23: དགེ་བཤེས་བློ་བཟང་ཟླ་བ།
A24: དགེ་འདུན་རིན་ཆེན། | B24: འབྲུག་རྗེ་མཁན་པོ ༦༩
A25: དངུལ་ཆུ་དྷརྨ་བྷ་དྲ། | B25: ཤཱཀྱའི་དགེ་སློང་དྷརྨ་བྷ་དྲ།
A26: དཔལ་མགོན་འཕགས་པ་ཀླུ་སྒྲུབ།
A27: དཔལ་ལྡན་ཕ་ར་རིན་ཆེན་གླིང་།
A28: དཔལ་ལྡན་ཤེས་རབ།
A29: དབྱངས་ཅན་གྲུབ་པའི་རྡོ་རྗེ་།།
A30: དབྱིག་གཉེན།
A31: པཎ་ཆེན ༠༢་བློ་བཟང་ཡེ་ཤེས།
A32: པཎ་ཆེན་ཐུབ་བསྟན་ཆོས་ཀྱི་ཉི་མ།
A33: པཎ་ཆེན་དྲི་མེད་བཤེས་གཉེན།
A34: པཎ་ཆེན་བསོད་ནམས་གྲགས་པ། | B34: བསོད་ནམས་གྲགས་པ། | C34: Paṇchen Sonam Drakpa
A35: པྲ་ཏི་དགེ་བཤེས་རིན་ཆེན་དོན་གྲུབ།
A36: པྲ་ཤཱ་སྟྲ་སེ།
A37: ཕ་བོང་ཁ་པ་བདེ་ཆེན་སྙིང་པོ།
A38: ཕྱག་ན་རྡོ་རྗེ།
A39: བཙུན་གཟུགས་པ།
A40: བྱམས་པ་མགོན་པོ།
...

Sheet དུམ་བུར་བཅད་སྟངས།
A1: Annotations (process) | B1: སྡེ་ཚན། | C1: ཚོན་མདོག། | D1: དོན་ཚན་དང་དཔེ། | E1: དོན་ཚན་དང་དཔེ།
A2: རྩ་བ་ལས་ཀ་བྱེད་སྟངས། | E2: རྩ་བའི་དོན་མཚམས་ཐུང་ཤོས་ལ་བཅད་དགོས། The root text segment covered in less than the ideal size, …)
A3: དཔེ་ཆའི་མཚན་བྱང། | B3: རང་འཇགས་བཞག་དགོས། | D3: དཔེར་ན། ༄༅། །སྒྲོལ་མར་ཕྱག་འཚལ་ཉེར་གཅིག་གིས་བསྟོད་པའི་རྣམ་བཤད་ཡིད་འཕྲོག་ཨུཏྤལའི་ཆུན་པོ་ཞེས་བྱ་བ་བཞུགས་སོ། ། | E3: ཀ༽ཡིག་ཕྲེང་(༣-༤)བར། ཡང་ན་ཡིག་འབྲུ(༧༥-༡༢༠)བར་དུ་བཅད་དགོས། ཁ༽ཡིག་ཕྲེང་ཐུང་ཤོས་དེ་ཡིག་ཕྲེང་གཅིག་གམ་ཡིག་འབྲུ་གཅིག་གི་བར་དུ་་བཅད་དགོས། Ideal size: 3 lines = between 75 to 90 syllables Maximum size: 4 lines = between 120 to 125 syllables Minimum size: less than 1 line = 1 syllable onwards, depending on the context (prose between two citations.
A4: Segment- words (root text) | B4: རྩ་ཚིག་དུམ་བུར་བཅད་སྟངས། | D4: རྩ་བའི་དོན་མཚམས་ཐུང་ཤོས་ལ་བཅད་དགོས། The root text segment covered in less than the ideal size, …) | E4: ས་བཅད། དཔེར་ན། མདོར་བསྟན་པ། རྒྱས་པར་བཤད་པ། ཕན་ཡོན་བསྟན་པའོ། དང་པོ་ནི།།
A5: Root Text-Alignment (རྩ་བ) | B5: རྩ་བར་ཨང་གྲངས་བཀོད་སྟངས། | C5: n/ | D5: ཨང་གྲངས། དཔེར་ན། 1. འཇམ་དཔལ་གཞོན་ནུར་གྱུར་པ་ལ་ཕྱག་འཚལ་ལོ། ། 2. གང་གིས་རྟེན་ཅིང་འབྲེལ་པར་འབྱུང་། ། འགག་པ་མེད་པ་སྐྱེ་མེད་པ། །​ ཆད་པ་མེད་པ་རྟག་མེད་པ། །འོང་བ་མེད་པ་འགྲོ་མེད་པ། །ཐ་དད་དོན་མིན་དོན་གཅིག་མིན། ། སྤྲོས་པ་ཉེར་ཞི་ཞི་བསྟན་པ། ། | E5: རྒྱུད་ལས།། ༼རྩ་བའི་ལུང་འདྲེན།༽ཞེས་གསུངས། དཔེར་ན། རྒྱུད་ལས།། ཕྱག་འཚལ་སྒྲོལ་མ་མྱུར་མ་དཔའ་མོ། ། ཞེས་གསུངས
B6: ལེའུ་ | D6: དཔེར་ན། ཚད་མ་རྣམ་འགྲེལ་གྱི་ཚིག་ལེའུར་བྱས་པ་ལས་ཚད་མ་གྲུབ་པ་ཞེས་བྱ་བ་ལེའུ་གཉིས་པའོ།། ། | E6: རྒྱུད་ལས།།༼ལུང་འདྲེན།༽ཞེས་གསུངས། དཔེར་ན། སྒྲོལ་རྒྱུད་མཚན་བརྒྱ་རྩ་བརྒྱད་པ་ལས་ཀྱང་། སྣ་ཚོགས་འཇིགས་པའི་རྒྱ་མཚོ་ལས། ། ཞེས་གསུངས་སོ། །
A7: འགྲེལ་བ་ལས་ཀ་བྱེད་སྟངས། | E7: bold དཔེར་ན། ཡེ་ཤེས་ཀྱི་སྤྱན་ནི་སྐད་ཅིག་གི་གློག་འཁྱུག་པ་དང་འདྲ་བར་ཤེས་བྱ་མཐའ་དག་སྐད་ཅིག་ལ་གཟིགས་མ།
A8: དཔེ་ཆའི་མཚན་བྱང། | B8: རང་འཇགས་བཞག་དགོས། | D8: དཔེར་ན། ༄༅། །སྒྲོལ་མར་ཕྱག་འཚལ་ཉེར་གཅིག་གིས་བསྟོད་པའི་རྣམ་བཤད་ཡིད་འཕྲོག་ཨུཏྤལའི་ཆུན་པོ་ཞེས་བྱ་བ་བཞུགས་སོ། ། | E8: Italic(bold) དཔེར་ན། སྐུ་གསུམ་ཡེ་ཤེས་ལྔ་ལྡན་བླ་མ་དང༌། །
A9: སྔོན་གླེང་དང་བར་སྐབས་ཀྱི་ཚིགས་སུ་བཅད་པ། | B9: Italic(bold) | C9: Italic(bold) | D9: Italic(bold) དཔེར་ན། སྐུ་གསུམ་ཡེ་ཤེས་ལྔ་ལྡན་བླ་མ་དང༌། ། | E9: དཔེར་ན། ༄༅། །སྒྲོལ་མར་ཕྱག་འཚལ་ཉེར་གཅིག་གིས་བསྟོད་པའི་རྣམ་བཤད་ཡིད་འཕྲོག་ཨུཏྤལའི་ཆུན་པོ་ཞེས་བྱ་བ་བཞུགས་སོ། །
A10: Segment- Sentence (commentary) | B10: འགྲེལ་བ་དུམ་བུར་བཅད་སྟངས། | C10: n/n/ | D10: ཀ༽ཡིག་ཕྲེང་(༣-༤)བར། ཡང་ན་ཡིག་འབྲུ(༧༥-༡༢༠)བར་དུ་བཅད་དགོས། ཁ༽ཡིག་ཕྲེང་ཐུང་ཤོས་དེ་ཡིག་ཕྲེང་གཅིག་གམ་ཡིག་འབྲུ་གཅིག་གི་བར་དུ་་བཅད་དགོས། Ideal size: 3 lines = between 75 to 90 syllables Maximum size: 4 lines = between 120 to 125 syllables Minimum size: less than 1 line = 1 syllable onwards, depending on the context (prose between two citations.
A11: Commontary-alignment (འགྲེལ་བ) | B11: འགྲེལ་བར་ཨང་གྲངས་བཀོད་སྟངས། ༼རྩ་འགྲེལ་མཐུད་སྒྲིག །༽ | D11: ཨང་གྲངས། དཔེར་ན། a) 1: རྩ་ཚིག་ཨང་གྲངས་གཅིག་རང་ཡོད་ན། b) 1,2,4,5: རྩ་ཚིག་ཨང་གྲངས་ ༡་ ༢་༤་༥་ཡོད་ན། only root text 1 and 2 and 4 and 5 c) 1-3: རྩ་ཚིག་ཨང་གྲངས་གཅིག་ནས་གསུམ་བར་མུ་མཐུད་ཡོད་ན། root text 1 and 2 and 3 d) 1-3,5,6: རྩ་ཚིག་ཨང་གྲངས་གཅིག་ནས་གསུམ་བར་མུ་མཐུད་ཡོད་པ་དང་བཞི་པ་མེད་པར་ལྔ་དང་དྲུག་པ་ཡོད་ན། root text 1 and 2 and 3 and 5 and 6 | E11: ཨང་གྲངས། དཔེར་ན། 1.༄༅། །ཨོཾ་རྗེ་བཙུན་མ་འཕགས་མ་སྒྲོལ་མ་ལ་ཕྱག་འཚལ་ལོ། ། 2. ཕྱག་འཚལ་སྒྲོལ་མ་མྱུར་མ་དཔའ་མོ། །
A12: Sapche segmentation | B12: ས་བཅད། | D12: ས་བཅད། དཔེར་ན། མདོར་བསྟན་པ། རྒྱས་པར་བཤད་པ། ཕན་ཡོན་བསྟན་པའོ། དང་པོ་ནི།། | E12: ཨང་གྲངས། དཔེར་ན། a) 1 རྩ་ཚིག་ཨང་གྲངས་གཅིག་རང་ཡོད་ན། b) 1,2,4,5: རྩ་ཚིག་ཨང་གྲངས་ ༡་ ༢་༤་༥་ཡོད་ན། only root text 1 and 2 and 4 and 5 c) 1-3: རྩ་ཚིག་ཨང་གྲངས་གཅིག་ནས་གསུམ་བར་མུ་མཐུད་ཡོད་ན། root text 1 and 2 and 3 d) 1-3,5,6: རྩ་ཚིག་ཨང་གྲངས་གཅིག་ནས་གསུམ་བར་མུ་མཐུད་ཡོད་པ་དང་བཞི་པ་མེད་པར་ལྔ་དང་དྲུག་པ་ཡོད་ན། root text 1 and 2 and 3 and 5 and 6
E13: དཔེར་ན། སངས་རྒྱས་ཆོས་དང་ཚོགས་ཀྱི་མཆོག་རྣམས་ལ། ༼ཚོགས་༽ དགེ་འདུན་
A14: Root text citation | B14: simple-text-origin
B15: རྩ་བའི་ལུང་འདྲེན། simple-text-citation | D15: རྒྱུད་ལས།། ༼རྩ་བའི་ལུང་འདྲེན།༽ཞེས་གསུངས། དཔེར་ན། རྒྱུད་ལས།། ཕྱག་འཚལ་སྒྲོལ་མ་མྱུར་མ་དཔའ་མོ། ། ཞེས་གསུངས
B16: simple-text-end
A18: Citation | B18: citation-origin
B19: ལུང་འདྲེན།citation-body | D19: རྒྱུད་ལས།།༼ལུང་འདྲེན།༽ཞེས་གསུངས། དཔེར་ན། སྒྲོལ་རྒྱུད་མཚན་བརྒྱ་རྩ་བརྒྱད་པ་ལས་ཀྱང་། སྣ་ཚོགས་འཇིགས་པའི་རྒྱ་མཚོ་ལས། ། ཞེས་གསུངས་སོ། །
B20: citation-end | E20: Italic(bold) དཔེར་ན། སྐུ་གསུམ་ཡེ་ཤེས་ལྔ་ལྡན་བླ་མ་དང༌། །
A22: Root text syllable | B22: འགྲེལ་བའི་ནང་གི་རྩ་བའི་ཚིག། | C22: bold | D22: bold དཔེར་ན། ཡེ་ཤེས་ཀྱི་སྤྱན་ནི་སྐད་ཅིག་གི་གློག་འཁྱུག་པ་དང་འདྲ་བར་ཤེས་བྱ་མཐའ་དག་སྐད་ཅིག་ལ་གཟིགས་མ།
A23: special དམིགས་གསལ་ | B23: འགྲེལ་བའི་ནང་གི་རྩ་བའི་ཚིག། | C23: bold | D23: དཔེར་ན། སངས་རྒྱས་ཆོས་དང་ཚོགས་ཀྱི་མཆོག་རྣམས་ལ། ༼ཚོགས་༽ དགེ་འདུན་
A25: small letter | B25: ཡིག་ཆུང་ | D25: to be implemented
A26: Preparing a Complex Text made by Gen Drupchen | D26: https://docs.google.com/document/d/124Ei1OoaA1COwgq3D9Y1egfzvGn1mAxxc0WtPhLNV8k/edit#heading=h.2asdhwqlbm1c
A27: རྩ་འགྲེལ་མཐུད་སྦྱོར་གྱི་རྩ་བའི་སྒྲིག་གཞི།། | D27: ཡིག་ཆ་རྙོག་འཛིངས་གྲ་སྒྲིག་བྱེད་ཚུལ། (བོད་འགྱུར།)

Sheet links
A1: Chinise
A2: The Pilot of Pecha.org

Sheet parsing specifications
A1: base text | B1: layer | C1: Annotations (process) | D1: markup | E1: description
C2: need to correct the selection of tsek characters. each syllable should contain the tsek or shad directly following it
A3: simple-text | C3: sentence | D3: \n | E3: each sentence is put on a separate line
A4: complex-text | C4: meaning-segment | D4: \n\n
A5: complex-text/simple-text | C5: sapche
A7: complex-text | B7: simple-text | C7: simple-text-origin | E7: optional, but can't exist on its own
A8: complex-text | B8: simple-text | C8: simple-text-citation | E8: mandatory
A9: complex-text | B9: simple-text | C9: simple-text-end | E9: optional, but can't exist on its own
A10: complex-text | B10: simple-text | C10: simple-text-syllable | D10: bold | E10: check if 1st char of syllable is bold. If True: process, else: ignore
A12: complex-text | B12: citation | C12: citation-origin | E12: optional, but can't exist on its own
A13: complex-text | B13: citation | C13: citation-body | E13: mandatory
A14: complex-text | B14: citation | C14: citation-end | E14: optional, but can't exist on its own
A16: complex-text | C16: verses | D16: Italic(bold)
A17: complex-text/simple-text | C17: title | D17: to be implemented
A18: complex-text/simple-text | C18: colophon | D18: to be implemented
A19: simple-text | C19: simple-text-segment | E19: each meaning-segment of the root text has a number+dot. normalization: if there is a space after the dot, delete it from the string. also strip any trailing spaces. 1. ༄༅། །ཨོཾ་རྗེ་བཙུན་མ་འཕགས་མ་སྒྲོལ་མ་ལ་ཕྱག་འཚལ་ལོ། ། 2. ཕྱག་འཚལ་སྒྲོལ་མ་མྱུར་མ་དཔའ་མོ། །
A20: complex-text | C20: simple-text-alignment | E20: a) "1" : རྩ་ཚིག་ཨང་གྲངས་གཅིག་རང་ཡོད་ན། b) "1,2,4,5" : རྩ་ཚིག་ཨང་གྲངས་ ༡་ ༢་༤་༥་ཡོད་ན། only root text 1 and 2 and 4 and 5 c) "1-3" : རྩ་ཚིག་ཨང་གྲངས་གཅིག་ནས་གསུམ་བར་མུ་མཐུད་ཡོད་ན། root text 1 and 2 and 3 d) "1-3,5,6" : རྩ་ཚིག་ཨང་གྲངས་གཅིག་ནས་གསུམ་བར་མུ་མཐུད་ཡོད་པ་དང་བཞི་པ་མེད་པར་ལྔ་དང་དྲུག་པ་ཡོད་ན། root text 1 and 2 and 3 and 5 and 6
A21: complex-text/simple-text | C21: small letter | D21: to be implemented

Sheet སྤྱོད་འཇུག་
A1: Main link | B1: doc link | C1: Github links | D1: Title | E1: Author Name | F1: Sources
A2: F69B2A09 བྱང་ཆུབ་སེམས་དཔའི་སྤྱོད་པ་ལ་འཇུག་པ། | B2: https://docs.google.com/document/d/1x634fk8A4ljiGbAgIUHB6KVbZYPAxjbwyT4c6_FK1KQ/edit?tab=t.0 | D2: སྤྱོད་འཇུག | E2: རྒྱལ་སྲས་ཞི་བ་ལྷ། | F2: https://library.bdrc.io/show/bdr:W8LS76623?s=q%3D%2522%25E0%25BD%2596%25E0%25BE%25B1%25E0%25BD%2584%25E0%25BC%258B%25E0%25BD%2586%25E0%25BD%25B4%25E0%25BD%2596%25E0%25BC%258B%25E0%25BD%25A6%25E0%25BD%25BA%25E0%25BD%2598%25E0%25BD%25A6%25E0%25BC%258B%25E0%25BD%2591%25E0%25BD%2594%25E0%25BD%25A0%25E0%25BD%25B2%25E0%25BC%258B%25E0%25BD%25A6%25E0%25BE%25A4%25E0%25BE%25B1%25E0%25BD%25BC%25E0%25BD%2591%25E0%25BC%258B%25E0%25BD%2594%25E0%25BC%258B%25E0%25BD%25A3%25E0%25BC%258B%25E0%25BD%25A0%25E0%25BD%2587%25E0%25BD%25B4%25E0%25BD%2582%25E0%25BC%258B%25E0%25BD%2594%25E0%25BC%258D%2522~1%26lg%3Dbo%26t%3DInstance%26f%3Dasset%2Cinc%2Ctmp%3ApossibleAccess%26f%3Dasset%2Cinc%2Ctmp%3AcatalogOnly%26n%3D11#open-viewer | G2: F69B2A09 བྱང་ཆུབ་སེམས་དཔའི་སྤྱོད་པ་ལ་འཇུག་པ། - Metadata
A3: R8C148471 | B3: https://docs.google.com/document/d/1Y7LHnBMEyk5TfotQy70_GLP1ZkmmGqVzpX3VSvaJT94/edit?tab=t.0 | C3: https://github.com/pechajobs/Chojuk-alignement/tree/a09388cf17e6415a37b6a8375f24051ede95a4d7/R8C148471 | D3: སྤྱོད་འཇུག་ཤེས་རབ་ཀྱི་ལེའུའི་ཚིག་དོན་གོ་སླ་བར་རྣམ་པར་བཤད་པ་ནོར་བུ་ཀེ་ཏ་ཀ | E3: འཇུ་མི་ཕམ་འཇམ་དབྱངས་རྣམ་རྒྱལ་རྒྱ་མཚོ།/Mipam Gyatso 菊·弥旁降央朗吉嘉措 | F3: http://purl.bdrc.io/resource/WA0XLDB48194DA341 | G3: R8C148471 སྤྱོད་འཇུག་ཤེས་རབ་ཀྱི་ལེའུའི་ཚིག་དོན་གོ་སླ་བར་རྣམ་པར་བཤད་པ་ནོར་བུ་ཀེ་ཏ་ཀ - Metadata
A4: R0507CCC1 | B4: https://docs.google.com/document/d/1YBb9M-WiIhQ2Y_KSQfYtBTiuJhh99lSmAS09WV6QEjQ/edit?tab=t.0 | C4: https://github.com/pechajobs/Chojuk-alignement/tree/a5864021f197c6cb67c151802650fbdbc05a1293/R0507CCC1 | D4: སྤྱོད་འཇུག་གི་ཚིག་འགྲེལ་གཅེས་བཏུས། | E4: ཀརྨ་བློ་གྲོས་ཆོས་དཔལ་བཟང་པོ། | F4: https://dharmaebooks.org/chojuk-thrangu/ | G4: R0507CCC1 སྤྱོད་འཇུག་གི་ཚིག་འགྲེལ་གཅེས་བཏུས། - Metadata
A5: R6F6BF20A | B5: https://docs.google.com/document/d/15sutVv4Bj_Ue44fVUPBQ7wfJebprk0HhBi0XDCp9eX4/edit?tab=t.0 | C5: https://github.com/pechajobs/Chojuk-alignement/tree/a09388cf17e6415a37b6a8375f24051ede95a4d7/R6F6BF20A | D5: བྱང་ཆུབ་སེམས་དཔའི་སྤྱོད་པ་ལ་འཇུག་པའི་རྣམ་པར་བཤད་པ་གཞུང་དོན་སྣང་བ། | E5: ལོ་ཙཱ་བ་བློ་གྲོས་དཔལ་བཟང་། / Jonang Lotsāwa Lodro Pel | F5: http://purl.bdrc.io/resource/WA1AC379 | G5: R6F6BF20A བྱང་ཆུབ་སེམས་དཔའི་སྤྱོད་པ་ལ་འཇུག་པའི་རྣམ་པར་བཤད་པ་གཞུང་དོན་སྣང་བ། - Metadata
A6: R099D5570 | B6: https://docs.google.com/document/d/1b4E1lt61Phk_HAbDDyLtEMfbKHVuaY-d3vuZp3n8vjg/edit?tab=t.0 | C6: https://github.com/pechajobs/Chojuk-alignement/tree/32cefe961276139c2099811922a221d3bf8ee7be/R099D5570 | D6: སྤྱོད་འཇུག་ཤེར་ལེའི་རྒྱ་ཆེར་འགྲེལ་མཆན་སྙིང་པོའི་དོན་གསལ་ཉིན་བྱེད་ཆེན་པོ། | E6: བྲག་གཡབ་བློ་གྲོས། | F6: http://purl.bdrc.io/resource/WA27521 | G6: R099D5570 སྤྱོད་འཇུག་ཤེར་ལེའི་རྒྱ་ཆེར་འགྲེལ་མཆན་སྙིང་པོའི་དོན་གསལ་ཉིན་བྱེད་ཆེན་པོ། - Metadata
A7: R41DCA1C2 | B7: https://docs.google.com/document/d/1bqxEkzf3rQhgOFpid7xn9NkBcTIoFQYH-kuHZDZeENM/edit?tab=t.0 | C7: https://github.com/pechajobs/Chojuk-alignement/tree/25f35cf4452b8680e727342d06a12b1be8cb015f/R41DCA1C2 | D7: སྤྱོད་འཇུག་ཤེས་རབ་ལེའུའི་མཆན་འགྲེལ་དོན་གསལ་མེ་ལོང་། | E7: གཞན་ཕན་ཆོས་ཀྱི་བློ་གྲོས། | F7: http://purl.bdrc.io/resource/WA0XLE3B6CBCF3107 | G7: R41DCA1C2 སྤྱོད་འཇུག་ཤེས་རབ་ལེའུའི་མཆན་འགྲེལ་དོན་གསལ་མེ་ལོང་། - Metadata
A8: R8D4B3A0C | B8: https://docs.google.com/document/d/13-jrjhCWgaHKc_Ru1_5MWmLYSuDQDl1sl7AyRea-Bg8/edit?tab=t.0 | C8: https://github.com/pechajobs/Chojuk-alignement/blob/67e6600a1d99c85f691e4d64484ce02d223325fb/R8D4B3A0C/%E0%BD%A6%E0%BE%A4%E0%BE%B1%E0%BD%BC%E0%BD%91%E0%BC%8B%E0%BD%A0%E0%BD%87%E0%BD%B4%E0%BD%82%E0%BC%8B%E0%BD%82%E0%BD%B2%E0%BC%8B%E0%BD%A0%E0%BD%96%E0%BE%B2%E0%BD%B4%E0%BC%8B%E0%BD%A0%E0%BD%82%E0%BE%B2%E0%BD%BA%E0%BD%A3%E0%BC%8B%E0%BD%91%E0%BD%96%E0%BD%B4%E0%BC%8B%E0%BD%98%E0%BD%A0%E0%BD%B2%E0%BC%8B%E0%BD%A3%E0%BD%98%E0%BC%8B%E0%BD%82%E0%BE%B1%E0%BD%B2%E0%BC%8B%E0%BD%A6%E0%BE%92%E0%BE%B2%E0%BD%BC%E0%BD%93%E0%BC%8B%E0%BD%98%E0%BC%8D | D8: སྤྱོད་འཇུག་གི་འབྲུ་འགྲེལ་དབུ་མའི་ལམ་གྱི་སྒྲོན་མ། | E8: འབྲུག་པ་པདྨ་དཀར་པོ། /Pema Karpo | F8: http://purl.bdrc.io/resource/WA1KG12679 | G8: R8D4B3A0C སྤྱོད་འཇུག་གི་འབྲུ་འགྲེལ་དབུ་མའི་ལམ་གྱི་སྒྲོན་མ། - Metadata
A9: R9DCD3008 | B9: https://docs.google.com/document/d/1-3zA1nB-7D2npVZHJk0zi6D4k7ijkQiRFXPYMUIj9ZQ/edit?tab=t.0 | C9: https://github.com/Esukhia/chojuk-alignement/tree/5e6354ddf1fc8dba2077f41616ed2264fb258dc4/D3873 | D9: ༄། །སྤྱོད་འཇུག་གི་རྣམ་པར་བཤད་པ་བཞུགས་སོ།། | E9: ནག་པོ་པ། | F9: http://purl.bdrc.io/resource/WA0RT3218 | G9: R9DCD3008 བྱང་ཆུབ་སེམས་དཔའི་སྤྱོད་པ་ལ་འཇུག་པའི་རྣམ་པར་བཤད་པའི་དཀའ་འགྲེལ། - Metadata
C10: སྤྱོད་འཇུག | G10: F69B2A09 བྱང་ཆུབ་སེམས་དཔའི་སྤྱོད་པ་ལ་འཇུག་པ། - Metadata
A11: R46DA1A6D | B11: https://docs.google.com/document/d/1cSXxEN8KNstPId_izM-pG-T_zsY8ENHSaD7YP00tTlI/edit?tab=t.0 | C11: https://github.com/pechajobs/Chojuk-alignement/blob/6c8ce62704b26d4c4e205fdabc6036869f2e5df7/R46DA1A6D/%E0%BD%A6%E0%BE%A4%E0%BE%B1%E0%BD%BC%E0%BD%91%E0%BC%8B%E0%BD%A0%E0%BD%87%E0%BD%B4%E0%BD%82%E0%BC%8B%E0%BD%9F%E0%BD%B2%E0%BD%93%E0%BC%8B%E0%BD%96%E0%BE%B2%E0%BD%B2%E0%BD%A6%E0%BC%8B%E0%BD%91%E0%BD%84%E0%BC%8B%E0%BD%9A%E0%BD%B2%E0%BD%82%E0%BC%8B%E0%BD%A0%E0%BD%82%E0%BE%B2%E0%BD%BA%E0%BD%A3%E0%BC%8B%E0%BD%A0%E0%BD%87%E0%BD%98%E0%BC%8B%E0%BD%91%E0%BD%96%E0%BE%B1%E0%BD%84%E0%BD%A6%E0%BC%8B%E0%BD%96%E0%BE%B3%E0%BC%8B%E0%BD%98%E0%BD%A0%E0%BD%B2%E0%BC%8B%E0%BD%9E%E0%BD%A3%E0%BC%8B%E0%BD%A3%E0%BD%B4%E0%BD%84%E0%BC%8B%E0%BD%96%E0%BD%91%E0%BD%B4%E0%BD%91%E0%BC%8B%E0%BD%A2%E0%BE%A9%E0%BD%B2%E0%BD%A0%E0%BD%B2%E0%BC%8B%E0%BD%90%E0%BD%B2%E0%BD%82%E0%BC%8B%E0%BD%94 | D11: སྤྱོད་འཇུག་ཟིན་བྲིས་དང་ཚིག་འགྲེལ་འཇམ་དབྱངས་བླ་མའི་ཞལ་ལུང་བདུད་རྩིའི་ཐིག་པ། | E11: མཁན་ཆེན་ཀུན་བཟང་དཔལ་ལྡན། /Kunzang Pelden | F11: http://purl.bdrc.io/resource/WA1KG22345 | G11: R46DA1A6D སྤྱོད་འཇུག་ཟིན་བྲིས་དང་ཚིག་འགྲེལ་འཇམ་དབྱངས་བླ་མའི་ཞལ་ལུང་བདུད་རྩིའི་ཐིག་པ། - Metadata
A12: R9A454784 | B12: https://docs.google.com/document/d/1t_VX792gWyP9uhEnMrKTiGVcrszgvPZ1XF2q1qxN-kY/edit?tab=t.0 | C12: https://github.com/Esukhia/chojuk-alignement/tree/5e6354ddf1fc8dba2077f41616ed2264fb258dc4/D3874-final | D12: བྱང་ཆུབ་སེམས་དཔའི་སྤྱོད་པ་ལ་འཇུག་པའི་ལེགས་པར་སྦྱར་བ། | E12: དགེ་བའི་ལྷ། /Kalyāṇadeva | F12: http://purl.bdrc.io/resource/WA0RT3219 | G12: R9A454784 བྱང་ཆུབ་སེམས་དཔའི་སྤྱོད་པ་ལ་འཇུག་པའི་ལེགས་པར་སྦྱར་བ། - Metadata
A13: R9ACAFA99 | B13: https://docs.google.com/document/d/1Dgt6edxQpJ5suStuNLdmaSJMSHeCVIe2p4Ktx0Tw9vw/edit?tab=t.0 | C13: https://github.com/Esukhia/chojuk-alignement/tree/5e6354ddf1fc8dba2077f41616ed2264fb258dc4/D3875-final | D13: བྱང་ཆུབ་ཀྱི་སྤྱོད་པ་ལ་འཇུག་པའི་དཀའ་འགྲེལ། | E13: ཤེས་རབ་འབྱུང་གནས་བློ་གྲོས། Prajñākaramati | F13: http://purl.bdrc.io/resource/WA21708 | G13: R9ACAFA99 བྱང་ཆུབ་སེམས་དཔའི་སྤྱོད་པ་ལ་འཇུག་པའི་དཀའ་འགྲེལ། - Metadata
A14: R9B72A4A4 | B14: https://docs.google.com/document/d/1gnacVGgouKZRD7y6A3T0V63Rd-sBnBuew-24YkdMmLA/edit?tab=t.0 | C14: https://github.com/Esukhia/chojuk-alignement/tree/5e6354ddf1fc8dba2077f41616ed2264fb258dc4/D3880-final | D14: བྱང་ཆུབ་ཀྱི་སྤྱོད་པ་ལ་འཇུག་པའི་དགོངས་པའི་འགྲེལ་པ་ཁྱད་པར་གསལ་བྱེད་ཅེས་བྱ་བ། | E14: པཎྜི་ཏ་བི་བྷུ་ཏི་ཙནྡྲ། པཎྜི་ཏ་བི་བྷུ་ཏི་ཙནྡྲ། Bhūticandra Vibhūticandra | F14: http://purl.bdrc.io/resource/WA0RT3225 | G14: R9B72A4A4 བྱང་ཆུབ་ཀྱི་སྤྱོད་པ་ལ་འཇུག་པའི་དགོངས་པའི་འགྲེལ་པ་ཁྱད་པར་གསལ་བྱེད། - Metadata
A15: RE07335AF | B15: https://docs.google.com/document/d/1YXVZw5tjZbJJXu68KyhcRzGjIYOB-JqYHPAgew5hNu4/edit?tab=t.0 | C15: https://github.com/Esukhia/chojuk-alignement/tree/5e6354ddf1fc8dba2077f41616ed2264fb258dc4/D3878-final | D15: བྱང་ཆུབ་སེམས་དཔའི་སྤྱོད་པ་ལ་འཇུག་པའི་དོན་བསྡུས་པ། | E15: གསེར་གླིང་རྒྱལ་པོ་དཔལ་ལྡན་ཆོས་སྐྱོང | F15: http://purl.bdrc.io/resource/WA0RT3224 | G15: RE07335AF བྱང་ཆུབ་སེམས་དཔའི་སྤྱོད་པ་ལ་འཇུག་པའི་དོན་སུམ་ཅུ་རྩ་དྲུག་ཏུ་བསྡུས་པ། - Metadata
A16: R6D6A899B | B16: https://docs.google.com/document/d/1GvDA4H1CyyvE8__u7neP2Sq7KhOFjyLVp7jYLH0ifn0/edit?tab=t.0 | C16: https://github.com/pechajobs/Chojuk-alignement/tree/b6a8f0ae16cb796939171f17f0c7a5ac9548e935/R6D6A899B | D16: བྱང་ཆུབ་སེམས་དཔའི་སྤྱོད་པ་ལ་འཇུག་པའི་འགྲེལ་པ་བྱང་ཆུབ་ཀྱི་སེམས་གསལ་བར་བྱེད་པ་ཟླ་བའི་འོད་ཟེར། | E16: བུ་སྟོན་རིན་ཆེན་གྲུབ། / Buton Rinchen Drub 布敦·仁钦珠｜布敦大师｜卜思端 | F16: http://purl.bdrc.io/resource/WA0XLF897C4B49D0C | G16: R6D6A899B བྱང་ཆུབ་སེམས་དཔའི་སྤྱོད་པ་ལ་འཇུག་པའི་འགྲེལ་པ་བྱང་ཆུབ་ཀྱི་སེམས་གསལ་བར་བྱེད་པ་ཟླ་བའི་འོད་ཟེར། - Metadata
A17: R8D5953D0 | B17: https://docs.google.com/document/d/1nYUPwahNkz3ZLlUQEOYPmrlYRCCakrfkZjhkCZaWuNw/edit?tab=t.0 | C17: https://github.com/pechajobs/Chojuk-alignement/tree/c50a4b9395d365bfb89d958455f1d71a6000c3c4/R8D5953D0 | D17: བྱང་ཆུབ་སེམས་དཔའི་སྤྱོད་པ་ལ་འཇུག་པ་ཞེས་བྱ་བའི་མཆན་འགྲེལ། | E17: རྒྱ་ཀོང་མཁན་ཆེན་གཞན་ཕན་ཆོས་ཀྱི་སྣང་བ། / Khenpo Zhenga Zhenpen Chokyi Nangwa | F17: http://purl.bdrc.io/resource/WA1KG3711 | G17: R8D5953D0 བྱང་ཆུབ་སེམས་དཔའི་སྤྱོད་པ་ལ་འཇུག་པ་ཞེས་བྱ་བའི་མཆན་འགྲེལ། - Metadata
A18: R8B4D6B85 | B18: https://docs.google.com/document/d/19LWtqvWkB7cfSjnWDziEGomm7RFm5187giDpmeVTlfw/edit?tab=t.0 | C18: https://github.com/pechajobs/Chojuk-alignement/tree/6e8eeaadfd3c9915a74ebd30166166b7c14f9efd/R8B4D6B85 | D18: སྤྱོད་འཇུག་རྣམ་བཤད་རྒྱལ་སྲས་འཇུག་ངོགས། | E18: རྒྱལ་ཚབ་དར་མ་རིན་ཆེན། /Gyeltsabje Darma Rinchen 贾策杰·达玛仁钦 | F18: http://purl.bdrc.io/resource/WA1KG4472 | G18: R8B4D6B85 སྤྱོད་འཇུག་རྣམ་བཤད་རྒྱལ་སྲས་འཇུག་ངོགས། - Metadata
A19: R6F6FCD5B | B19: https://docs.google.com/document/d/1h4rb4mh-W0a8ZVDqSlskf74qJktVcx8n36oxQQ2K860/edit?tab=t.0 | C19: https://github.com/pechajobs/Chojuk-alignement/tree/c759aa715acd3d553e43848440ac64abfbef022d/R6F6FCD5B | D19: སྤྱོད་འཇུག་འགྲེལ་པ་ངེས་ལེགས་མཛོད། | E19: སྨུག་སངས་ཀརྨ་ཚེ་དཔལ། | F19: http://purl.bdrc.io/resource/WA0XLBD800F29DAEE | G19: R6F6FCD5B སྤྱོད་འཇུག་འགྲེལ་པ་ངེས་ལེགས་མཛོད། - Metadata
A20: R48E48ED0 | B20: https://docs.google.com/document/d/13z1Qw3hFGRe1A-Fb7ohcLZ15LIs3x7JQVPZYI2p_9_E/edit?tab=t.0 | C20: https://github.com/pechajobs/Chojuk-alignement/tree/c759aa715acd3d553e43848440ac64abfbef022d/R48E48ED0 | D20: སྤྱོད་འཇུག་ཤེར་ལེའི་འབྲུ་འགྲེལ་སྲིན་ཆུང་འཕོངས་ཀྱི་འོད་སྣང་། | E20: དཔྱི་ས་བློ་གྲོས་རྒྱ་མཚོ། | F20: http://purl.bdrc.io/resource/WA0XLBF4622B2DDE7 | G20: R48E48ED0 སྤྱོད་འཇུག་ཤེར་ལེའི་འབྲུ་འགྲེལ་སྲིན་ཆུང་འཕོངས་ཀྱི་འོད་སྣང་། - Metadata
A21: RBF0E36D6 | B21: https://docs.google.com/document/d/1GCfKVqY51EsyYJHjFNQXgYgTnfm6KgPfz-rNDXK6xlc/edit?tab=t.0 | C21: https://github.com/pechajobs/Chojuk-alignement/tree/c50a4b9395d365bfb89d958455f1d71a6000c3c4/RBF0E36D6 | D21: སྤྱོད་འཇུག་ཤེས་རབ་ལེའུའི་ཊཱིཀྐ་བློ་གསལ་བ་ཞེས་པ། | E21: ཙོང་ཁ་པ་བློ་བཟང་གྲགས་པ། Tsongkhapa Lobzang Drakpa 宗喀巴 | F21: http://purl.bdrc.io/resource/WA0XLFF0FB9D3BEB1 | G21: RBF0E36D6 སྤྱོད་འཇུག་ཤེས་རབ་ལེའུའི་ཊཱིཀྐ་བློ་གསལ་བ་ཞེས་པ། - Metadata
A22: R4FF99FF8 | B22: https://docs.google.com/document/d/1HmlQOVSyNjRG4yO_wjC1JHT_ZACR-1FRrH22uBJ6qLU/edit?tab=t.0 | C22: https://github.com/pechajobs/Chojuk-alignement/tree/c759aa715acd3d553e43848440ac64abfbef022d/R4FF99FF8 | D22: སྤྱོད་འཇུག་འགྲེལ་པ་གཞུང་དོན་རབ་གསལ་སྣང་བ། | E22: ས་བཟང་མ་ཏི་པཎ་ཆེན་བློ་གྲོས་རྒྱལ་མཚན།/Sabzang Mati Paṇchen Lodro Gyeltsen | F22: http://purl.bdrc.io/resource/WA1660 | G22: R4FF99FF8 སྤྱོད་འཇུག་འགྲེལ་པ་གཞུང་དོན་རབ་གསལ་སྣང་བ། - Metadata
... A28: R7F788F87 | B28: R7F788F87 བྱང་ཆུབ་སེམས་དཔའི་སྤྱོད་པ་ལ་འཇུག་པའི་འགྲེལ་བཤད་རྒྱལ་སྲས་རྒྱ་མཚོའི་ཡོན་ཏན་རིན་པོ་ཆེ་མི་ཟད་འཇོ་བའི་བུམ་བཟང་། Segm | C28: R7F788F87 བྱང་ཆུབ་སེམས་དཔའི་སྤྱོད་པ་ལ་འཇུག་པའི་འགྲེལ་བཤད་རྒྱལ་སྲས་རྒྱ་མཚོའི་ཡོན་ཏན་རིན་པོ་ཆེ་མི་ཟད་འཇོ་བའི་བུམ་བཟང་། Segm | D28: སྤྱོད་འཇུག་གི་འགྲེལ་བཤད། | E28: ཐུབ་བསྟན་ཆོས་ཀྱི་གྲགས་པ། | F28: http://purl.bdrc.io/resource/WA0XL552C599021F7 | G28: R7F788F87 བྱང་ཆུབ་སེམས་དཔའི་སྤྱོད་པ་ལ་འཇུག་པའི་འགྲེལ་བཤད་རྒྱལ་སྲས་རྒྱ་མཚོའི་ཡོན་ཏན་རིན་པོ་ཆེ་མི་ཟད་འཇོ་བའི་བུམ་བཟང་། - Metadata

Sheet General list
A1: ཨང་ ༼ID༽དང་མཚན་བྱང་། (Title) | B1: མཛད་པ་པོ། (Author) | C1: དྲྭ་ཐག།
A2: M0C370E5C རྒྱུན་ཆགས་གསུམ་པ།
A3: ME33A3E85 སྐྱབས་འགྲོ།
A4: M0CD39D50 སྐྱབས་སེམས་སྦྲགས་མ།
A5: སྐྱབས་འགྲོ་སེམས་བསྐྱེད། དཀོན་མཆོག་གསུམ་ལ་བདག་སྐྱབས་མཆི།།
A6: M1C3CC04D ཚད་མེད་བཞི།
A7: M114EE7D1 མཆོད་སྤྲིན།
A8: M2C6E5CCC སྤྱན་འདྲེན།
A9: M6FBF8888 ཁྲུས་གསོལ།
A10: M3F2C426A ཡན་ལག་བདུན་པ།
A11: M6F628B74 མཎྜལ་རྒྱས་བསྡུས་ཁག། | B11: མཁན་མཉམ་མ། ༼ཆོས་བརྒྱུད་རིགས་མེད།༽
A12: M4B6747F6 སྟོན་པ་ཐུབ་པའི་དབང་པོར་བསྟོད་པ།
A13: M0E8E854E སྐབས་གསུམ་པ།
A14: M62BC0A5A མཁའ་མཉམ་མ། ༼ཆོས་བརྒྱུད་རིགས་མེད།༽
A15: M5F7D7BD9 གསོལ་འདེབས་དད་པའི་མེ་ཏོག། | B15: རེད་མདའ་བ་གཞོན་ནུ་བློ་གྲོས། | C15: http://purl.bdrc.io/resource/WA0XL869A1B0053B1
A16: M1A8D26D2 ༧གོང་ས་༧སྐྱབས་མགོན་ཆེན་པོའི་ཞབས་བརྟན་གསོལ་འདེབས་འཆི་མེད་གྲུབ་པའི་དབྱངས་སྙན། | B16: ཁྲི་བྱང ༠༣་བློ་བཟང་ཡེ་ཤེས་བསྟན་འཛིན་རྒྱ་མཚོ། | C16: http://purl.bdrc.io/resource/WA8CZ98
A17: M5D39973F ༧ཞགས་བརྟན་གསོལ་འདེབས་གདོད་ནས་རྣམ་དག་མ།
A18: M4C5C4568 འཇམ་པའི་དབྱངས་ཀྱི་བསྟོད་པ་གང་བློ་མ།
A19: M02BDDB5E འཕགས་བསྟོད། | B19: སློབ་དཔོན་རྡོ་རྗེ་གོ་ཆ། | C19: https://library.bdrc.io/show/bdr:WA0XL6FDADE554BB2?s=q%3D%2522%25E0%25BD%2582%25E0%25BD%2584%25E0%25BC%258B%25E0%25BD%2596%25E0%25BE%25B3%25E0%25BD%25BC%25E0%25BC%258B%25E0%25BD%2598%25E0%25BC%258D%2522~1%26lg%3Dbo%26t%3DWork%26pg%3D1%26f%3Dgenres%2Cinc%2Cbdr%3AO3JW530910MS9278%26f%3Dgenres%2Cinc%2Cbdr%3AT67%26f%3Dgenres%2Cinc%2Cbdr%3AT1254%26s%3Dwork%2520title%26n%3D2
A20: MDAFBF633 སྒྲོལ་མ་ཉེར་གཅིག་གི་བསྟོད་པ།
A21: M29C34F4A ཤེས་རབ་སྙིང་པོ།
A22: M1BC4B06C ལྷ་མོར་བསྟོད་པ་ཡན་ལག་བདུན་པ།
A23: M4B99B48B གནས་ཆུང་འཕྲིན་བསྐུལ་བདེ་གཤེགས་རིགས་ལྔ།
A24: M5351D533 བསྟན་འབར་མ།
A25: M05869193 བདེན་ཚིག་སྨོན་ལམ
A26: M48EB0584 སྐྱབས་འགྲོ་མ་རྣམ་བཞི་མ། | B26: ཏཱ་ལའི་བླ་མ ༡༤ | C26: https://library.bdrc.io/show/bdr:MW1KG4532_B9BC38
A27: M0EE74BA5 ཐུབ་སྐུའི་འདོད་གསོལ།
A28: M4AD3186A གསོལ་འདེབས་སྨོན་ཚིག་བདེན་པའི་རྔ་སྒྲ།
A29: M4B7B8820 སྟོན་པའི་མཚན་སྔགས། ཨོཾ་མུ་ནི་མུ་ནི་མཧཱ་མུ་ནི་ཡེ་སྭཱཧཱ།
A30: M4A445631 ནཱ་ལེཎྜའི་པཎ་གྲུབ་བཅུ་བདུན་གྱི་གསོལ་འདེབས།
A31: M6E1314B9 ཚིག་བདུན་གསོལ་འདེབས།
A32: M1D558340 གསོལ་འདེབས་ཐུགས་དམ་གནད་བསྐུལ། | B32: མདོ་མང་གཏེར་ཆེན་རྡོ་རྗེ་བདེ་ཆེན་གླིང་པ། | C32: http://purl.bdrc.io/resource/WA00EGS1016759
A33: M74459E05 སློབ་དཔོན་རིན་པོ་ཆེའི་མཚན་སྔགས། ཨོྃ་ཨཱཿ ཧཱུྃ༔ བཛྲ་གུ་རུ་པདྨ་སིདྡྷི་ཧཱུྃ།
A34: M4DDF63DD དམིགས་བརྩེ་མ།
A35: M4FC4BDD5 ༸གོང་ས་མཆོག་གི་མཚན་སྔགས། ཨོཾ་ཨཱཿ གུ་རུ་བཛྲ་དྷ་ར་བྷ་ཌྜཱ་ར་ཀ་མཉྫུ་ཤྲཱི་ཝཱ་གིནྡྲ་སུ་མ་ཏི་ཛྙཱ་ན་ཤཱ་ས་ན་དྷ་ར་ས་མུ་དྲ་ཤྲཱི་བྷ་དྲ་སརྦ་སིདྡྷི་ཧཱུྃ་ཧཱུྃ།།
A36: M9A635F5D ཐེགས་པ་ཆེན་པོའི་བློ་སྦྱོང་གི་རྩ་ཚིག།
A37: M0AD47D2B བློ་སྦྱོང་ཚིག་བརྒྱད་མ།
A38: M3FA75475 བཟང་སྤྱོད་སྨོན་ལམ། | B38: གླང་རི་ཐང་པ་རྡོ་རྗེ་སེངྒེ | C38: https://library.bdrc.io/show/bdr:WA0XL54767FB51BE6?s=q%3D%2522%25E0%25BD%2596%25E0%25BE%25B3%25E0%25BD%25BC%25E0%25BC%258B%25E0%25BD%25A6%25E0%25BE%25A6%25E0%25BE%25B1%25E0%25BD%25BC%25E0%25BD%2584%25E0%25BC%258B%25E0%25BD%259A%25E0%25BD%25B2%25E0%25BD%2582%25E0%25BC%258B%25E0%25BD%2596%25E0%25BD%25A2%25E0%25BE%2592%25E0%25BE%25B1%25E0%25BD%2591%25E0%25BC%258B%25E0%25BD%2598%25E0%25BC%258D%2522~1%26lg%3Dbo%26t%3DWork%26n%3D7
A39: M3BAF99BFའཕགས་པ་སྤྱན་རས་གཟིགས་ཀྱི་མཚན་སྔགས། ཨོཾ་མ་ཎི་པ་དྨེ་ཧཱུྃ། | C39: http://purl.bdrc.io/resource/WA0RT3711
A40: M0DA10740 ཚེ་རབས་རྗེས་འཛིན།
...
